Workbook
Name _._IMPUESTOS_SOBRE_COMBUSTIBLES_Y_GAS_NATURAL: #REF!
Name _._IMPUESTOS_SOBRE_ENERGIA_ELECTRICA: #REF!
Name AJESTA: #REF!
Name ALFA: #REF!
Name CEMENTO: #REF!
Name CICESP: #REF!
Name COMB: #REF!
Name CONSTRUC: #REF!
Name COPA: #N/A
Name COPARTICIPACION_FEDERAL__LEY_N__23548: #REF!
Name DIFTA: #REF!
Name EEI: #REF!
Name EMPLEO: #REF!
Name EPH: #REF!
Name EPH_POB: #REF!
Name EXCEDENTE_DEL_10__SEGUN_EL_TOPE_ASIGNADO_A__BUENOS_AIRES__LEY_N__23621: #REF!
Name FAE_BOVINOS: #REF!
Name FONDO_COMPENSADOR_DE_DESEQUILIBRIOS_FISCALES_PROVINCIALES: #REF!
Name FONDO_EDUCATIVO__LEY_N__23906_ART._3_Y_4: #REF!
Name FONDO_ESPECIAL_DE_DESARROLLO_ELECTRICO_DEL_INTERIOR__LEYES_NROS._23966_ART._19_Y_24065: #REF!
Name FONDO_NACIONAL_DE_LA_VIVIENDA__LEY_N__23966_ART._18: #REF!
Name GAS: #REF!
Name ICC_FM: #REF!
Name IDL_UTDT: #REF!
Name IND_ACEITERA: #REF!
Name IPC_GBA: #REF!
Name IPC_NAC: #REF!
Name IPC_SFE: #REF!
Name IPM: #REF!
Name IPMPE: #REF!
Name IRR: #REF!
Name L_: #N/A
Name LACTEA: #REF!
Name MAQ_AGR: #REF!
Name NA: #REF!
Name O: #N/A
Name OBRAS_DE_INFRAESTRUCTURA__LEY_N__23966_ART._19: #REF!
Name OBRAS_DE_INFRAESTRUCTURA_BASICA_SOCIAL_Y_NECESIDADES_BASICAS_INSATISFECHAS__LEY_N__23621: #REF!
Name ORGANISMOS_DE_VIALIDAD__LEY_N__23966_ART._19: #REF!
Name PATENTES: #REF!
Name PBG: #REF!
Name PGCLAS: #REF!
Name PGCREC: #REF!
Name REC: #REF!
Name sct: #REF!
Name SEGURIDAD_SOCIAL___BS._PERS._NO_INCORP._AL_PROCESO_ECONOMICO__LEY_N__23966__ART._30: #REF!
Name SEGURIDAD_SOCIAL___IVA__LEY_N__23966_ART._5_PTO._2: #REF!
Name SUMA_FIJA_FINANCIADA_CON__LA_COPARTICIPACION_FEDERAL_DE_NACION__LEY_N__23621_ART._1: #REF!
Name TOTAL: #REF!
Name TRANSFERENCIA_DE_SERVICIOS__LEY_N__24049_Y_COMPLEMENTARIAS: #REF!
Name Trigo: #REF!
Name VARCRI: #REF!
Name VARTA: #REF!
Name VENTAS: #REF!
Name XCER: #REF!

Sheet INDICE
E2: Centro de Estudios y Servicios - Bolsa de Comercio de Santa Fe -
E3: San Martín 2231 - CP 3000 - Santa Fe - Argentina
E4: Teléfono: (0342) 4845800
E5: Email: ces@bcsf.com.ar
E6: Website: https://bcsf.com.ar/ces/ o bien http://www.bcsf.com.ar
C8: BASE DE DATOS ESTADÍSTICOS DE LAS 24 JURISDICCIONES (PROVINCIAS Y CABA)
C10: Última actualización: 29/6/2026 | F10: < Próxima fecha de publicación: mayo 2027 >
C11: Aclaración general: los datos subrayados implican estimaciones propias y los datos en azul la existencia de una fórmula. Los datos en amarillo oscuro indican información provisoria.
C13: Recursos | F13: Frecuencia | G13: Nº de series | H13: Fecha de inicio
C14: 1.1. Recursos totales por provincia | F14: Anual | G14: =COLUMNS('1.1'!B:Z) -> 25 | H14: 1992
C15: 1.1.1. Recursos corrientes por provincia | F15: Anual | G15: =COLUMNS('1.1.1'!B:Z) -> 25 | H15: 1992
B16: Ir a | C16: 1.1.1.1. Recursos tributarios de origen provincial por provincia | F16: Anual | G16: =COLUMNS('1.1.1.1'!B:Z) -> 25 | H16: 1992
C17: 1.1.1.1.1 Ingresos brutos | F17: Anual | G17: =COLUMNS('1.1.1.1.1'!B:Z) -> 25 | H17: 1992
C18: 1.1.1.1.2 Inmobiliario | F18: Anual | G18: =COLUMNS('1.1.1.1.2'!B:Z) -> 25 | H18: 1992
C19: 1.1.1.1.3 Sellos | F19: Anual | G19: =COLUMNS('1.1.1.1.3'!B:Z) -> 25 | H19: 1992
C20: 1.1.1.1.4 Automotores | F20: Anual | G20: =COLUMNS('1.1.1.1.4'!B:Z) -> 25 | H20: 1992
C21: 1.1.1.1.5 Otros impuestos provinciales | F21: Anual | G21: =COLUMNS('1.1.1.1.5'!B:Z) -> 25 | H21: 1992
C22: 1.1.1.2. Recursos de origen nacional (coparticipación) por provincia | F22: Anual | G22: =COLUMNS('1.1.1.2'!B:Z) -> 25 | H22: 1992
C23: 1.1.1.3. Recursos no tributarios por provincia | F23: Anual | G23: =COLUMNS('1.1.1.3'!B:Z) -> 25 | H23: 1992
C24: 1.1.1.3.1. Regalías por provincia | F24: Anual | G24: =COLUMNS('1.1.1.3.1'!B:Z) -> 25 | H24: 1992
C25: 1.1.1.4. Venta de bienes y servicios de la Administración pública por provincia | F25: Anual | G25: =COLUMNS('1.1.1.4'!B:Z) -> 25 | H25: 1996
C26: 1.1.1.5. Rentas de la propiedad por provincia | F26: Anual | G26: =COLUMNS('1.1.1.5'!B:Z) -> 25 | H26: 1996
C27: 1.1.1.6. Transferencias corrientes por provincia | F27: Anual | G27: =COLUMNS('1.1.1.6'!B:Z) -> 25 | H27: 1992
C28: 1.1.2. Recursos de capital por provincia | F28: Anual | G28: =COLUMNS('1.1.2'!B:Z) -> 25 | H28: 1992
C29: 1.2. Recaudación de Impuestos Nacionales por provincia | F29: Anual | G29: =COLUMNS('1.2'!B:Z) -> 25 | H29: 2001
C30: 1.2.1. Recaudación del Impuesto al Valor Agregado (IVA) por provincia | F30: Anual | G30: =COLUMNS('1.2.1'!B:AA) -> 26 | H30: 2001
C31: 1.2.2. Recaudación del Impuesto a las Ganancias por provincia | F31: Anual | G31: =COLUMNS('1.2.2'!B:AA) -> 26 | H31: 2001
C32: 1.2.3. Recaudación del Impuesto a los Bienes Personales por provincia | F32: Anual | G32: =COLUMNS('1.2.3'!B:AA) -> 26 | H32: 2001
C33: 1.2.4. Recaudación del Impuesto a las Cuentas Corrientes por provincia | F33: Anual | G33: =COLUMNS('1.2.4'!B:AA) -> 26 | H33: 2001
C34: 1.2.4.1. Porción no coparticipable del Impuesto al Cheque por provincia | F34: Anual | G34: =COLUMNS('1.2.4.1'!B:AA) -> 26 | H34: 2001
C35: 1.2.5. Recaudación de las Ganancias mínimas presuntas por provincia | F35: Anual | G35: =COLUMNS('1.2.5'!B:AA) -> 26 | H35: 2001
C36: 1.2.6. Recaudación de los Impuestos Internos por provincia | F36: Anual | G36: =COLUMNS('1.2.6'!B:AA) -> 26 | H36: 2001
C37: 1.2.7. Recaudación del Monotributo por provincia | F37: Anual | G37: =COLUMNS('1.2.7'!B:AA) -> 26 | H37: 2001
C38: 1.2.8. Recaudación de otros impuestos por provincia | F38: Anual | G38: =COLUMNS('1.2.8'!B:AA) -> 26 | H38: 2001
C39: 1.2.9. Recaudación de Impuestos Aduaneros por provincia | F39: Anual | G39: =COLUMNS('1.2.9'!B:AA) -> 26 | H39: 2001
C40: Gastos | F40: Frecuencia | G40: Nº de series | H40: Fecha de inicio
C41: 2. Gasto público total por provincia | F41: Anual | G41: =COLUMNS('2'!B:Z) -> 25 | H41: 1992
C42: 2.1. Gastos corrientes por provincia | F42: Anual | G42: =COLUMNS('2.1'!B:Z) -> 25 | H42: 1992
C43: 2.1.1. Gasto de consumo | F43: Anual | G43: =COLUMNS('2.1.1'!B:Z) -> 25 | H43: 1992
C44: 2.1.1.1 Gasto público en personal por provincia | F44: Anual | G44: =COLUMNS('2.1.1.1'!B:Z) -> 25 | H44: 1992
...

Sheet Deflactores
A3: Título | B3: Precios minoristas al consumidor. Deflactor.
A4: Fuentes | B4: INDEC - UBA - IPEC - Congreso - IDECBA
A6: Empalmes | B6: IPC Nacional - BA City - IPC Santa Fe - Congreso - IPC Nacional
A8: Unidad de medida | B8: Indice base 2016=100
B9: Media geométrica anual
A10: 1992 | B10: 5.2104099
A11: 1993 | B11: 5.6288937
A12: 1994 | B12: 5.7685507
A13: 1995 | B13: 6.0736247
A14: 1996 | B14: 6.121665
A15: 1997 | B15: 5.9241227
A16: 1998 | B16: 5.705479
A17: 1999 | B17: 5.4667572
A18: 2000 | B18: 5.2520619
A19: 2001 | B19: 5.1211084
A20: 2002 | B20: 7.4273682
A21: 2003 | B21: 8.972316
... A44: 2026 | B44: 12345.954
A45: 2027 | B45: #N/A
A46: 2028 | B46: #N/A
A47: 2029 | B47: #N/A
A48: 2030 | B48: #N/A

Sheet 1.1
A2: Título | B2: Recursos totales por provincia | N2: =B2 -> Recursos totales por provincia
A3: Fuente | B3: Dirección Nacional de Asuntos Provinciales - Ministerio de Economía de la Nación | N3: =B3 -> Dirección Nacional de Asuntos Provinciales - Ministerio de Economía de la Nación
A5: VOLVER AL ÍNDICE | B5: Administración Pública No Financiera | N5: =B5 -> Administración Pública No Financiera
A7: Unidad de medida | B7: Millones de pesos constantes de 2016 | C7: Millones de pesos constantes de 2016 | D7: Millones de pesos constantes de 2016 | E7: Millones de pesos constantes de 2016 | F7: Millones de pesos constantes de 2016 | G7: Millones de pesos constantes de 2016 | H7: Millones de pesos constantes de 2016 | I7: Millones de pesos constantes de 2016 | J7: Millones de pesos constantes de 2016 | K7: Millones de pesos constantes de 2016 | L7: Millones de pesos constantes de 2016 | M7: Millones de pesos constantes de 2016 | N7: Millones de pesos constantes de 2016 | O7: Millones de pesos constantes de 2016 | P7: Millones de pesos constantes de 2016 | Q7: Millones de pesos constantes de 2016 | R7: Millones de pesos constantes de 2016 | S7: Millones de pesos constantes de 2016 | T7: Millones de pesos constantes de 2016 | U7: Millones de pesos constantes de 2016 | V7: Millones de pesos constantes de 2016 | W7: Millones de pesos constantes de 2016 | X7: Millones de pesos constantes de 2016 | Y7: Millones de pesos constantes de 2016 | Z7: Millones de pesos constantes de 2016
A8: CÓDIGO | B8: 1.1.1 | C8: 1.1.2 | D8: 1.1.3 | E8: 1.1.4 | F8: 1.1.5 | G8: 1.1.6 | H8: 1.1.7 | I8: 1.1.8 | J8: 1.1.9 | K8: 1.1.10 | L8: 1.1.11 | M8: 1.1.12 | N8: 1.1.13 | O8: 1.1.14 | P8: 1.1.15 | Q8: 1.1.16 | R8: 1.1.17 | S8: 1.1.18 | T8: 1.1.19 | U8: 1.1.20 | V8: 1.1.21 | W8: 1.1.22 | X8: 1.1.23 | Y8: 1.1.24 | Z8: 1.1.25
A9: Jurisdicción | B9: C.A.B.A. | C9: Buenos Aires | D9: Catamarca | E9: Córdoba | F9: Corrientes | G9: Chaco | H9: Chubut | I9: Entre Ríos | J9: Formosa | K9: Jujuy | L9: La Pampa | M9: La Rioja | N9: Mendoza | O9: Misiones | P9: Neuquén | Q9: Río Negro | R9: Salta | S9: San Juan | T9: San Luis | U9: Santa Cruz | V9: Santa Fe | W9: Santiago del Estero | X9: Tucumán | Y9: Tierra del Fuego | Z9: Total
A10: 1992 | B10: =+'[1]1.1'!B10/Deflactores!$B10*100 -> 49533.76 | C10: =+'[1]1.1'!C10/Deflactores!$B10*100 -> 108900.62 | D10: =+'[1]1.1'!D10/Deflactores!$B10*100 -> 7317.3868 | E10: =+'[1]1.1'!E10/Deflactores!$B10*100 -> 35578.963 | F10: =+'[1]1.1'!F10/Deflactores!$B10*100 -> 10534.012 | G10: =+'[1]1.1'!G10/Deflactores!$B10*100 -> 12972.108 | H10: =+'[1]1.1'!H10/Deflactores!$B10*100 -> 7941.7935 | I10: =+'[1]1.1'!I10/Deflactores!$B10*100 -> 15930.065 | ... Y10: =+'[1]1.1'!Y10/Deflactores!$B10*100 -> 4552.5522 | Z10: =SUM(B10:Y10) -> 429906.96
A11: 1993 | B11: =+'[1]1.1'!B11/Deflactores!$B11*100 -> 47815.322 | C11: =+'[1]1.1'!C11/Deflactores!$B11*100 -> 124752.93 | D11: =+'[1]1.1'!D11/Deflactores!$B11*100 -> 6561.7605 | E11: =+'[1]1.1'!E11/Deflactores!$B11*100 -> 34585.191 | F11: =+'[1]1.1'!F11/Deflactores!$B11*100 -> 10546.072 | G11: =+'[1]1.1'!G11/Deflactores!$B11*100 -> 11947.266 | H11: =+'[1]1.1'!H11/Deflactores!$B11*100 -> 7174.6776 | I11: =+'[1]1.1'!I11/Deflactores!$B11*100 -> 15590.782 | ... Y11: =+'[1]1.1'!Y11/Deflactores!$B11*100 -> 5021.6576 | Z11: =SUM(B11:Y11) -> 453144.58
A12: 1994 | B12: =+'[1]1.1'!B12/Deflactores!$B12*100 -> 47857.118 | C12: =+'[1]1.1'!C12/Deflactores!$B12*100 -> 134248.46 | D12: =+'[1]1.1'!D12/Deflactores!$B12*100 -> 6748.6535 | E12: =+'[1]1.1'!E12/Deflactores!$B12*100 -> 37148.948 | F12: =+'[1]1.1'!F12/Deflactores!$B12*100 -> 10349.902 | G12: =+'[1]1.1'!G12/Deflactores!$B12*100 -> 12218.679 | H12: =+'[1]1.1'!H12/Deflactores!$B12*100 -> 7443.124 | I12: =+'[1]1.1'!I12/Deflactores!$B12*100 -> 17242.033 | ... Y12: =+'[1]1.1'!Y12/Deflactores!$B12*100 -> 5720.6479 | Z12: =SUM(B12:Y12) -> 474478.7
A13: 1995 | B13: =+'[1]1.1'!B13/Deflactores!$B13*100 -> 44100.353 | C13: =+'[1]1.1'!C13/Deflactores!$B13*100 -> 126065.66 | D13: =+'[1]1.1'!D13/Deflactores!$B13*100 -> 6276.6211 | E13: =+'[1]1.1'!E13/Deflactores!$B13*100 -> 33206.098 | F13: =+'[1]1.1'!F13/Deflactores!$B13*100 -> 9669.3592 | G13: =+'[1]1.1'!G13/Deflactores!$B13*100 -> 11612.631 | H13: =+'[1]1.1'!H13/Deflactores!$B13*100 -> 7913.131 | I13: =+'[1]1.1'!I13/Deflactores!$B13*100 -> 15810.644 | ... Y13: =+'[1]1.1'!Y13/Deflactores!$B13*100 -> 5060.7236 | Z13: =SUM(B13:Y13) -> 439509.51
A14: 1996 | B14: =+'[1]1.1'!B14/Deflactores!$B14*100 -> 44704.347 | C14: =+'[1]1.1'!C14/Deflactores!$B14*100 -> 132894.53 | D14: =+'[1]1.1'!D14/Deflactores!$B14*100 -> 6609.2752 | E14: =+'[1]1.1'!E14/Deflactores!$B14*100 -> 36657.594 | F14: =+'[1]1.1'!F14/Deflactores!$B14*100 -> 10216.165 | G14: =+'[1]1.1'!G14/Deflactores!$B14*100 -> 12627.356 | H14: =+'[1]1.1'!H14/Deflactores!$B14*100 -> 8022.7395 | I14: =+'[1]1.1'!I14/Deflactores!$B14*100 -> 19782.281 | ... Y14: =+'[1]1.1'!Y14/Deflactores!$B14*100 -> 5264.8489 | Z14: =SUM(B14:Y14) -> 475048.7
A15: 1997 | B15: =+'[1]1.1'!B15/Deflactores!$B15*100 -> 48870.654 | C15: =+'[1]1.1'!C15/Deflactores!$B15*100 -> 173553.99 | D15: =+'[1]1.1'!D15/Deflactores!$B15*100 -> 8566.3244 | E15: =+'[1]1.1'!E15/Deflactores!$B15*100 -> 40783.694 | F15: =+'[1]1.1'!F15/Deflactores!$B15*100 -> 12383.846 | G15: =+'[1]1.1'!G15/Deflactores!$B15*100 -> 14869.676 | H15: =+'[1]1.1'!H15/Deflactores!$B15*100 -> 8738.5506 | I15: =+'[1]1.1'!I15/Deflactores!$B15*100 -> 19729.035 | ... Y15: =+'[1]1.1'!Y15/Deflactores!$B15*100 -> 5993.5222 | Z15: =SUM(B15:Y15) -> 550583.7
A16: 1998 | B16: =+'[1]1.1'!B16/Deflactores!$B16*100 -> 56362.653 | C16: =+'[1]1.1'!C16/Deflactores!$B16*100 -> 164334.7 | D16: =+'[1]1.1'!D16/Deflactores!$B16*100 -> 9049.7995 | E16: =+'[1]1.1'!E16/Deflactores!$B16*100 -> 44042.636 | F16: =+'[1]1.1'!F16/Deflactores!$B16*100 -> 12878.81 | G16: =+'[1]1.1'!G16/Deflactores!$B16*100 -> 16729.25 | H16: =+'[1]1.1'!H16/Deflactores!$B16*100 -> 8943.1066 | I16: =+'[1]1.1'!I16/Deflactores!$B16*100 -> 21009.681 | ... Y16: =+'[1]1.1'!Y16/Deflactores!$B16*100 -> 6301.9858 | Z16: =SUM(B16:Y16) -> 580330.28
A17: 1999 | B17: =+'[1]1.1'!B17/Deflactores!$B17*100 -> 58308.079 | C17: =+'[1]1.1'!C17/Deflactores!$B17*100 -> 171713.86 | D17: =+'[1]1.1'!D17/Deflactores!$B17*100 -> 9253.6812 | E17: =+'[1]1.1'!E17/Deflactores!$B17*100 -> 43247.449 | F17: =+'[1]1.1'!F17/Deflactores!$B17*100 -> 13506.874 | G17: =+'[1]1.1'!G17/Deflactores!$B17*100 -> 16573.692 | H17: =+'[1]1.1'!H17/Deflactores!$B17*100 -> 9321.8282 | I17: =+'[1]1.1'!I17/Deflactores!$B17*100 -> 21353.703 | ... Y17: =+'[1]1.1'!Y17/Deflactores!$B17*100 -> 6659.4956 | Z17: =SUM(B17:Y17) -> 590363.74
A18: 2000 | B18: =+'[1]1.1'!B18/Deflactores!$B18*100 -> 61747.929 | C18: =+'[1]1.1'!C18/Deflactores!$B18*100 -> 173830.19 | D18: =+'[1]1.1'!D18/Deflactores!$B18*100 -> 9473.3443 | E18: =+'[1]1.1'!E18/Deflactores!$B18*100 -> 45642.615 | F18: =+'[1]1.1'!F18/Deflactores!$B18*100 -> 14155.757 | G18: =+'[1]1.1'!G18/Deflactores!$B18*100 -> 17610.265 | H18: =+'[1]1.1'!H18/Deflactores!$B18*100 -> 11323.1 | I18: =+'[1]1.1'!I18/Deflactores!$B18*100 -> 21274.777 | ... Y18: =+'[1]1.1'!Y18/Deflactores!$B18*100 -> 7913.8243 | Z18: =SUM(B18:Y18) -> 619705.93
A19: 2001 | B19: =+'[1]1.1'!B19/Deflactores!$B19*100 -> 57323.535 | C19: =+'[1]1.1'!C19/Deflactores!$B19*100 -> 154675.83 | D19: =+'[1]1.1'!D19/Deflactores!$B19*100 -> 9772.0085 | E19: =+'[1]1.1'!E19/Deflactores!$B19*100 -> 43067.06 | F19: =+'[1]1.1'!F19/Deflactores!$B19*100 -> 14149.066 | G19: =+'[1]1.1'!G19/Deflactores!$B19*100 -> 17073.245 | H19: =+'[1]1.1'!H19/Deflactores!$B19*100 -> 11081.385 | I19: =+'[1]1.1'!I19/Deflactores!$B19*100 -> 21591.692 | ... Y19: =+'[1]1.1'!Y19/Deflactores!$B19*100 -> 8148.8149 | Z19: =SUM(B19:Y19) -> 586517.33
A20: 2002 | B20: =+'[1]1.1'!B20/Deflactores!$B20*100 -> 38952.1 | C20: =+'[1]1.1'!C20/Deflactores!$B20*100 -> 117828.27 | D20: =+'[1]1.1'!D20/Deflactores!$B20*100 -> 6589.6587 | E20: =+'[1]1.1'!E20/Deflactores!$B20*100 -> 31268.19 | F20: =+'[1]1.1'!F20/Deflactores!$B20*100 -> 8882.0277 | G20: =+'[1]1.1'!G20/Deflactores!$B20*100 -> 12278.732 | H20: =+'[1]1.1'!H20/Deflactores!$B20*100 -> 11514.026 | I20: =+'[1]1.1'!I20/Deflactores!$B20*100 -> 13658.288 | ... Y20: =+'[1]1.1'!Y20/Deflactores!$B20*100 -> 5846.3452 | Z20: =SUM(B20:Y20) -> 436016.46
A21: 2003 | B21: =+'[1]1.1'!B21/Deflactores!$B21*100 -> 44548.383 | C21: =+'[1]1.1'!C21/Deflactores!$B21*100 -> 128496.43 | D21: =+'[1]1.1'!D21/Deflactores!$B21*100 -> 7522.4472 | E21: =+'[1]1.1'!E21/Deflactores!$B21*100 -> 35270.105 | F21: =+'[1]1.1'!F21/Deflactores!$B21*100 -> 9804.7917 | G21: =+'[1]1.1'!G21/Deflactores!$B21*100 -> 13393.365 | H21: =+'[1]1.1'!H21/Deflactores!$B21*100 -> 11974.689 | I21: =+'[1]1.1'!I21/Deflactores!$B21*100 -> 15261.116 | ... Y21: =+'[1]1.1'!Y21/Deflactores!$B21*100 -> 6138.7099 | Z21: =SUM(B21:Y21) -> 475573.58
... A41: 2023 | B41: =+'[1]1.1'!B41/Deflactores!$B41*100 -> 159438.69 | C41: =+'[1]1.1'!C41/Deflactores!$B41*100 -> 422561.47 | D41: =+'[1]1.1'!D41/Deflactores!$B41*100 -> 25125.202 | E41: =+'[1]1.1'!E41/Deflactores!$B41*100 -> 133084.63 | F41: =+'[1]1.1'!F41/Deflactores!$B41*100 -> 35635.024 | G41: =+'[1]1.1'!G41/Deflactores!$B41*100 -> 49320.928 | H41: =+'[1]1.1'!H41/Deflactores!$B41*100 -> 31385.397 | I41: =+'[1]1.1'!I41/Deflactores!$B41*100 -> 56074.272 | ... Y41: =+'[1]1.1'!Y41/Deflactores!$B41*100 -> 17643.706 | Z41: =SUM(B41:Y41) -> 1547711.3
A42: 2024 | B42: =+'[1]1.1'!B42/Deflactores!$B42*100 -> 136724.55 | C42: =+'[1]1.1'!C42/Deflactores!$B42*100 -> 346937.22 | D42: =+'[1]1.1'!D42/Deflactores!$B42*100 -> 19472.677 | E42: =+'[1]1.1'!E42/Deflactores!$B42*100 -> 113915.37 | F42: =+'[1]1.1'!F42/Deflactores!$B42*100 -> 30361.665 | G42: =+'[1]1.1'!G42/Deflactores!$B42*100 -> 39854.436 | H42: =+'[1]1.1'!H42/Deflactores!$B42*100 -> 27401.45 | I42: =+'[1]1.1'!I42/Deflactores!$B42*100 -> 46575.722 | ... Y42: =+'[1]1.1'!Y42/Deflactores!$B42*100 -> 14697.342 | Z42: =_xlfn.AGGREGATE(9,6,B42:Y42) -> 1281921.9
A43: 2025 | B43: =+'[1]1.1'!B43/Deflactores!$B43*100 -> 135318.15 | C43: =+'[1]1.1'!C43/Deflactores!$B43*100 -> 344851.9 | D43: =+'[1]1.1'!D43/Deflactores!$B43*100 -> 19341.284 | E43: =+'[1]1.1'!E43/Deflactores!$B43*100 -> 118489.84 | F43: =+'[1]1.1'!F43/Deflactores!$B43*100 -> 30968.179 | G43: =+'[1]1.1'!G43/Deflactores!$B43*100 -> 41698.106 | H43: =+'[1]1.1'!H43/Deflactores!$B43*100 -> 27407.546 | I43: =+'[1]1.1'!I43/Deflactores!$B43*100 -> 48489.916 | ... Y43: =+'[1]1.1'!Y43/Deflactores!$B43*100 -> 14112.09 | Z43: =SUM(B43:Y43) -> #N/A
A44: 2026 | B44: =+'[1]1.1'!B44/Deflactores!$B44*100 -> #N/A | C44: =+'[1]1.1'!C44/Deflactores!$B44*100 -> #N/A | D44: =+'[1]1.1'!D44/Deflactores!$B44*100 -> #N/A | E44: =+'[1]1.1'!E44/Deflactores!$B44*100 -> #N/A | F44: =+'[1]1.1'!F44/Deflactores!$B44*100 -> #N/A | G44: =+'[1]1.1'!G44/Deflactores!$B44*100 -> #N/A | H44: =+'[1]1.1'!H44/Deflactores!$B44*100 -> #N/A | I44: =+'[1]1.1'!I44/Deflactores!$B44*100 -> #N/A | ... Y44: =+'[1]1.1'!Y44/Deflactores!$B44*100 -> #N/A | Z44: =SUM(B44:Y44) -> #N/A
A45: 2027 | B45: =+'[1]1.1'!B45/Deflactores!$B45*100 -> #N/A | C45: =+'[1]1.1'!C45/Deflactores!$B45*100 -> #N/A | D45: =+'[1]1.1'!D45/Deflactores!$B45*100 -> #N/A | E45: =+'[1]1.1'!E45/Deflactores!$B45*100 -> #N/A | F45: =+'[1]1.1'!F45/Deflactores!$B45*100 -> #N/A | G45: =+'[1]1.1'!G45/Deflactores!$B45*100 -> #N/A | H45: =+'[1]1.1'!H45/Deflactores!$B45*100 -> #N/A | I45: =+'[1]1.1'!I45/Deflactores!$B45*100 -> #N/A | ... Y45: =+'[1]1.1'!Y45/Deflactores!$B45*100 -> #N/A | Z45: =SUM(B45:Y45) -> #N/A
A46: 2028 | B46: =+'[1]1.1'!B46/Deflactores!$B46*100 -> #N/A | C46: =+'[1]1.1'!C46/Deflactores!$B46*100 -> #N/A | D46: =+'[1]1.1'!D46/Deflactores!$B46*100 -> #N/A | E46: =+'[1]1.1'!E46/Deflactores!$B46*100 -> #N/A | F46: =+'[1]1.1'!F46/Deflactores!$B46*100 -> #N/A | G46: =+'[1]1.1'!G46/Deflactores!$B46*100 -> #N/A | H46: =+'[1]1.1'!H46/Deflactores!$B46*100 -> #N/A | I46: =+'[1]1.1'!I46/Deflactores!$B46*100 -> #N/A | ... Y46: =+'[1]1.1'!Y46/Deflactores!$B46*100 -> #N/A | Z46: =SUM(B46:Y46) -> #N/A
A47: 2029 | B47: =+'[1]1.1'!B47/Deflactores!$B47*100 -> #N/A | C47: =+'[1]1.1'!C47/Deflactores!$B47*100 -> #N/A | D47: =+'[1]1.1'!D47/Deflactores!$B47*100 -> #N/A | E47: =+'[1]1.1'!E47/Deflactores!$B47*100 -> #N/A | F47: =+'[1]1.1'!F47/Deflactores!$B47*100 -> #N/A | G47: =+'[1]1.1'!G47/Deflactores!$B47*100 -> #N/A | H47: =+'[1]1.1'!H47/Deflactores!$B47*100 -> #N/A | I47: =+'[1]1.1'!I47/Deflactores!$B47*100 -> #N/A | ... Y47: =+'[1]1.1'!Y47/Deflactores!$B47*100 -> #N/A | Z47: =SUM(B47:Y47) -> #N/A
A48: 2030 | B48: =+'[1]1.1'!B48/Deflactores!$B48*100 -> #N/A | C48: =+'[1]1.1'!C48/Deflactores!$B48*100 -> #N/A | D48: =+'[1]1.1'!D48/Deflactores!$B48*100 -> #N/A | E48: =+'[1]1.1'!E48/Deflactores!$B48*100 -> #N/A | F48: =+'[1]1.1'!F48/Deflactores!$B48*100 -> #N/A | G48: =+'[1]1.1'!G48/Deflactores!$B48*100 -> #N/A | H48: =+'[1]1.1'!H48/Deflactores!$B48*100 -> #N/A | I48: =+'[1]1.1'!I48/Deflactores!$B48*100 -> #N/A | ... Y48: =+'[1]1.1'!Y48/Deflactores!$B48*100 -> #N/A | Z48: =SUM(B48:Y48) -> #N/A

Sheet 1.1.1
A2: Título | B2: Recursos corrientes por provincia | N2: =B2 -> Recursos corrientes por provincia
A3: Fuente | B3: Dirección Nacional de Asuntos Provinciales - Ministerio de Economía de la Nación | N3: =B3 -> Dirección Nacional de Asuntos Provinciales - Ministerio de Economía de la Nación
A5: VOLVER AL ÍNDICE | B5: Administración Pública No Financiera | N5: =B5 -> Administración Pública No Financiera
A7: Unidad de medida | B7: Millones de pesos constantes de 2016 | C7: Millones de pesos constantes de 2016 | D7: Millones de pesos constantes de 2016 | E7: Millones de pesos constantes de 2016 | F7: Millones de pesos constantes de 2016 | G7: Millones de pesos constantes de 2016 | H7: Millones de pesos constantes de 2016 | I7: Millones de pesos constantes de 2016 | J7: Millones de pesos constantes de 2016 | K7: Millones de pesos constantes de 2016 | L7: Millones de pesos constantes de 2016 | M7: Millones de pesos constantes de 2016 | N7: Millones de pesos constantes de 2016 | O7: Millones de pesos constantes de 2016 | P7: Millones de pesos constantes de 2016 | Q7: Millones de pesos constantes de 2016 | R7: Millones de pesos constantes de 2016 | S7: Millones de pesos constantes de 2016 | T7: Millones de pesos constantes de 2016 | U7: Millones de pesos constantes de 2016 | V7: Millones de pesos constantes de 2016 | W7: Millones de pesos constantes de 2016 | X7: Millones de pesos constantes de 2016 | Y7: Millones de pesos constantes de 2016 | Z7: Millones de pesos constantes de 2016
A8: CÓDIGO | B8: 1.1.1.1 | C8: 1.1.1.2 | D8: 1.1.1.3 | E8: 1.1.1.4 | F8: 1.1.1.5 | G8: 1.1.1.6 | H8: 1.1.1.7 | I8: 1.1.1.8 | J8: 1.1.1.9 | K8: 1.1.1.10 | L8: 1.1.1.11 | M8: 1.1.1.12 | N8: 1.1.1.13 | O8: 1.1.1.14 | P8: 1.1.1.15 | Q8: 1.1.1.16 | R8: 1.1.1.17 | S8: 1.1.1.18 | T8: 1.1.1.19 | U8: 1.1.1.20 | V8: 1.1.1.21 | W8: 1.1.1.22 | X8: 1.1.1.23 | Y8: 1.1.1.24 | Z8: 1.1.1.25
A9: Jurisdicción | B9: C.A.B.A. | C9: Buenos Aires | D9: Catamarca | E9: Córdoba | F9: Corrientes | G9: Chaco | H9: Chubut | I9: Entre Ríos | J9: Formosa | K9: Jujuy | L9: La Pampa | M9: La Rioja | N9: Mendoza | O9: Misiones | P9: Neuquén | Q9: Río Negro | R9: Salta | S9: San Juan | T9: San Luis | U9: Santa Cruz | V9: Santa Fe | W9: Santiago del Estero | X9: Tucumán | Y9: Tierra del Fuego | Z9: Total
A10: 1992 | B10: =+'[1]1.1.1'!B10/Deflactores!$B10*100 -> 40593.665 | C10: =+'[1]1.1.1'!C10/Deflactores!$B10*100 -> 113440.29 | D10: =+'[1]1.1.1'!D10/Deflactores!$B10*100 -> 6698.6499 | E10: =+'[1]1.1.1'!E10/Deflactores!$B10*100 -> 32717.264 | F10: =+'[1]1.1.1'!F10/Deflactores!$B10*100 -> 10015.013 | G10: =+'[1]1.1.1'!G10/Deflactores!$B10*100 -> 12118.197 | H10: =+'[1]1.1.1'!H10/Deflactores!$B10*100 -> 7063.1274 | I10: =+'[1]1.1.1'!I10/Deflactores!$B10*100 -> 14730.308 | ... Y10: =+'[1]1.1.1'!Y10/Deflactores!$B10*100 -> 4353.4504 | Z10: =SUM(B10:Y10) -> 414391.17
A11: 1993 | B11: =+'[1]1.1.1'!B11/Deflactores!$B11*100 -> 47756.135 | C11: =+'[1]1.1.1'!C11/Deflactores!$B11*100 -> 122257.51 | D11: =+'[1]1.1.1'!D11/Deflactores!$B11*100 -> 6510.4396 | E11: =+'[1]1.1.1'!E11/Deflactores!$B11*100 -> 34275.532 | F11: =+'[1]1.1.1'!F11/Deflactores!$B11*100 -> 10426.807 | G11: =+'[1]1.1.1'!G11/Deflactores!$B11*100 -> 11802.811 | H11: =+'[1]1.1.1'!H11/Deflactores!$B11*100 -> 7148.7973 | I11: =+'[1]1.1.1'!I11/Deflactores!$B11*100 -> 15527.239 | ... Y11: =+'[1]1.1.1'!Y11/Deflactores!$B11*100 -> 4679.7458 | Z11: =SUM(B11:Y11) -> 440021.69
A12: 1994 | B12: =+'[1]1.1.1'!B12/Deflactores!$B12*100 -> 47819.778 | C12: =+'[1]1.1.1'!C12/Deflactores!$B12*100 -> 132221.66 | D12: =+'[1]1.1.1'!D12/Deflactores!$B12*100 -> 6715.625 | E12: =+'[1]1.1.1'!E12/Deflactores!$B12*100 -> 36832.345 | F12: =+'[1]1.1.1'!F12/Deflactores!$B12*100 -> 10161.447 | G12: =+'[1]1.1.1'!G12/Deflactores!$B12*100 -> 12084.682 | H12: =+'[1]1.1.1'!H12/Deflactores!$B12*100 -> 7288.1521 | I12: =+'[1]1.1.1'!I12/Deflactores!$B12*100 -> 16559.584 | ... Y12: =+'[1]1.1.1'!Y12/Deflactores!$B12*100 -> 5554.1585 | Z12: =SUM(B12:Y12) -> 464291.59
A13: 1995 | B13: =+'[1]1.1.1'!B13/Deflactores!$B13*100 -> 44073.349 | C13: =+'[1]1.1.1'!C13/Deflactores!$B13*100 -> 124840.17 | D13: =+'[1]1.1.1'!D13/Deflactores!$B13*100 -> 6039.2967 | E13: =+'[1]1.1.1'!E13/Deflactores!$B13*100 -> 32806.799 | F13: =+'[1]1.1.1'!F13/Deflactores!$B13*100 -> 9396.5801 | G13: =+'[1]1.1.1'!G13/Deflactores!$B13*100 -> 11475.289 | H13: =+'[1]1.1.1'!H13/Deflactores!$B13*100 -> 7690.4559 | I13: =+'[1]1.1.1'!I13/Deflactores!$B13*100 -> 15473.804 | ... Y13: =+'[1]1.1.1'!Y13/Deflactores!$B13*100 -> 5013.4416 | Z13: =SUM(B13:Y13) -> 428165.79
A14: 1996 | B14: =+'[1]1.1.1'!B14/Deflactores!$B14*100 -> 44525.439 | C14: =+'[1]1.1.1'!C14/Deflactores!$B14*100 -> 131007.65 | D14: =+'[1]1.1.1'!D14/Deflactores!$B14*100 -> 6561.3442 | E14: =+'[1]1.1.1'!E14/Deflactores!$B14*100 -> 36141.521 | F14: =+'[1]1.1.1'!F14/Deflactores!$B14*100 -> 9995.6538 | G14: =+'[1]1.1.1'!G14/Deflactores!$B14*100 -> 12500.87 | H14: =+'[1]1.1.1'!H14/Deflactores!$B14*100 -> 7810.3105 | I14: =+'[1]1.1.1'!I14/Deflactores!$B14*100 -> 16965.498 | ... Y14: =+'[1]1.1.1'!Y14/Deflactores!$B14*100 -> 5106.4553 | Z14: =SUM(B14:Y14) -> 456305.71
A15: 1997 | B15: =+'[1]1.1.1'!B15/Deflactores!$B15*100 -> 48860.733 | C15: =+'[1]1.1.1'!C15/Deflactores!$B15*100 -> 150729.2 | D15: =+'[1]1.1.1'!D15/Deflactores!$B15*100 -> 8305.362 | E15: =+'[1]1.1.1'!E15/Deflactores!$B15*100 -> 40300.241 | F15: =+'[1]1.1.1'!F15/Deflactores!$B15*100 -> 12117.402 | G15: =+'[1]1.1.1'!G15/Deflactores!$B15*100 -> 14500.884 | H15: =+'[1]1.1.1'!H15/Deflactores!$B15*100 -> 8638.7151 | I15: =+'[1]1.1.1'!I15/Deflactores!$B15*100 -> 19148.236 | ... Y15: =+'[1]1.1.1'!Y15/Deflactores!$B15*100 -> 5634.3483 | Z15: =SUM(B15:Y15) -> 520191.27
A16: 1998 | B16: =+'[1]1.1.1'!B16/Deflactores!$B16*100 -> 56357.513 | C16: =+'[1]1.1.1'!C16/Deflactores!$B16*100 -> 161933.82 | D16: =+'[1]1.1.1'!D16/Deflactores!$B16*100 -> 8840.1403 | E16: =+'[1]1.1.1'!E16/Deflactores!$B16*100 -> 43558.126 | F16: =+'[1]1.1.1'!F16/Deflactores!$B16*100 -> 12712.385 | G16: =+'[1]1.1.1'!G16/Deflactores!$B16*100 -> 15794.526 | H16: =+'[1]1.1.1'!H16/Deflactores!$B16*100 -> 8627.8052 | I16: =+'[1]1.1.1'!I16/Deflactores!$B16*100 -> 20492.326 | ... Y16: =+'[1]1.1.1'!Y16/Deflactores!$B16*100 -> 6103.0367 | Z16: =SUM(B16:Y16) -> 561420.75
A17: 1999 | B17: =+'[1]1.1.1'!B17/Deflactores!$B17*100 -> 58302.701 | C17: =+'[1]1.1.1'!C17/Deflactores!$B17*100 -> 160762.12 | D17: =+'[1]1.1.1'!D17/Deflactores!$B17*100 -> 9106.0331 | E17: =+'[1]1.1.1'!E17/Deflactores!$B17*100 -> 42787.372 | F17: =+'[1]1.1.1'!F17/Deflactores!$B17*100 -> 13381.618 | G17: =+'[1]1.1.1'!G17/Deflactores!$B17*100 -> 15953.105 | H17: =+'[1]1.1.1'!H17/Deflactores!$B17*100 -> 9017.9958 | I17: =+'[1]1.1.1'!I17/Deflactores!$B17*100 -> 20343.509 | ... Y17: =+'[1]1.1.1'!Y17/Deflactores!$B17*100 -> 6382.7161 | Z17: =SUM(B17:Y17) -> 568718.41
A18: 2000 | B18: =+'[1]1.1.1'!B18/Deflactores!$B18*100 -> 61742.917 | C18: =+'[1]1.1.1'!C18/Deflactores!$B18*100 -> 171663.67 | D18: =+'[1]1.1.1'!D18/Deflactores!$B18*100 -> 9306.6971 | E18: =+'[1]1.1.1'!E18/Deflactores!$B18*100 -> 45146.796 | F18: =+'[1]1.1.1'!F18/Deflactores!$B18*100 -> 13620.906 | G18: =+'[1]1.1.1'!G18/Deflactores!$B18*100 -> 17022.383 | H18: =+'[1]1.1.1'!H18/Deflactores!$B18*100 -> 11069.054 | I18: =+'[1]1.1.1'!I18/Deflactores!$B18*100 -> 21003.349 | ... Y18: =+'[1]1.1.1'!Y18/Deflactores!$B18*100 -> 7581.5362 | Z18: =SUM(B18:Y18) -> 606331
A19: 2001 | B19: =+'[1]1.1.1'!B19/Deflactores!$B19*100 -> 57318.719 | C19: =+'[1]1.1.1'!C19/Deflactores!$B19*100 -> 152927.5 | D19: =+'[1]1.1.1'!D19/Deflactores!$B19*100 -> 9457.5836 | E19: =+'[1]1.1.1'!E19/Deflactores!$B19*100 -> 42618.582 | F19: =+'[1]1.1.1'!F19/Deflactores!$B19*100 -> 13593.764 | G19: =+'[1]1.1.1'!G19/Deflactores!$B19*100 -> 16442.817 | H19: =+'[1]1.1.1'!H19/Deflactores!$B19*100 -> 10706.13 | I19: =+'[1]1.1.1'!I19/Deflactores!$B19*100 -> 20841.758 | ... Y19: =+'[1]1.1.1'!Y19/Deflactores!$B19*100 -> 7754.628 | Z19: =SUM(B19:Y19) -> 572454.2
A20: 2002 | B20: =+'[1]1.1.1'!B20/Deflactores!$B20*100 -> 38666.685 | C20: =+'[1]1.1.1'!C20/Deflactores!$B20*100 -> 116713.55 | D20: =+'[1]1.1.1'!D20/Deflactores!$B20*100 -> 6440.4261 | E20: =+'[1]1.1.1'!E20/Deflactores!$B20*100 -> 29536.661 | F20: =+'[1]1.1.1'!F20/Deflactores!$B20*100 -> 8744.6553 | G20: =+'[1]1.1.1'!G20/Deflactores!$B20*100 -> 11972.859 | H20: =+'[1]1.1.1'!H20/Deflactores!$B20*100 -> 11228.531 | I20: =+'[1]1.1.1'!I20/Deflactores!$B20*100 -> 13469.34 | ... Y20: =+'[1]1.1.1'!Y20/Deflactores!$B20*100 -> 5525.4426 | Z20: =SUM(B20:Y20) -> 427109.32
A21: 2003 | B21: =+'[1]1.1.1'!B21/Deflactores!$B21*100 -> 44452.879 | C21: =+'[1]1.1.1'!C21/Deflactores!$B21*100 -> 126455.63 | D21: =+'[1]1.1.1'!D21/Deflactores!$B21*100 -> 7400.2702 | E21: =+'[1]1.1.1'!E21/Deflactores!$B21*100 -> 33964.166 | F21: =+'[1]1.1.1'!F21/Deflactores!$B21*100 -> 9588.91 | G21: =+'[1]1.1.1'!G21/Deflactores!$B21*100 -> 12910.886 | H21: =+'[1]1.1.1'!H21/Deflactores!$B21*100 -> 11687.632 | I21: =+'[1]1.1.1'!I21/Deflactores!$B21*100 -> 15006.982 | ... Y21: =+'[1]1.1.1'!Y21/Deflactores!$B21*100 -> 5812.6142 | Z21: =SUM(B21:Y21) -> 466512.84
... A48: 2030 | B48: =+'[1]1.1.1'!B48/Deflactores!$B48*100 -> #N/A | C48: =+'[1]1.1.1'!C48/Deflactores!$B48*100 -> #N/A | D48: =+'[1]1.1.1'!D48/Deflactores!$B48*100 -> #N/A | E48: =+'[1]1.1.1'!E48/Deflactores!$B48*100 -> #N/A | F48: =+'[1]1.1.1'!F48/Deflactores!$B48*100 -> #N/A | G48: =+'[1]1.1.1'!G48/Deflactores!$B48*100 -> #N/A | H48: =+'[1]1.1.1'!H48/Deflactores!$B48*100 -> #N/A | I48: =+'[1]1.1.1'!I48/Deflactores!$B48*100 -> #N/A | ... Y48: =+'[1]1.1.1'!Y48/Deflactores!$B48*100 -> #N/A | Z48: =SUM(B48:Y48) -> #N/A

Sheet 1.1.1.1
A2: Título | B2: Recursos tributarios de origen provincial (Impuestos provinciales) por provincia | N2: =B2 -> Recursos tributarios de origen provincial (Impuestos provinciales) por provincia
A3: Fuente | B3: Dirección Nacional de Asuntos Provinciales - Ministerio de Economía de la Nación | N3: =B3 -> Dirección Nacional de Asuntos Provinciales - Ministerio de Economía de la Nación
A5: VOLVER AL ÍNDICE | B5: Administración Pública No Financiera | N5: =B5 -> Administración Pública No Financiera
A7: Unidad de medida | B7: Millones de pesos constantes de 2016 | C7: Millones de pesos constantes de 2016 | D7: Millones de pesos constantes de 2016 | E7: Millones de pesos constantes de 2016 | F7: Millones de pesos constantes de 2016 | G7: Millones de pesos constantes de 2016 | H7: Millones de pesos constantes de 2016 | I7: Millones de pesos constantes de 2016 | J7: Millones de pesos constantes de 2016 | K7: Millones de pesos constantes de 2016 | L7: Millones de pesos constantes de 2016 | M7: Millones de pesos constantes de 2016 | N7: Millones de pesos constantes de 2016 | O7: Millones de pesos constantes de 2016 | P7: Millones de pesos constantes de 2016 | Q7: Millones de pesos constantes de 2016 | R7: Millones de pesos constantes de 2016 | S7: Millones de pesos constantes de 2016 | T7: Millones de pesos constantes de 2016 | U7: Millones de pesos constantes de 2016 | V7: Millones de pesos constantes de 2016 | W7: Millones de pesos constantes de 2016 | X7: Millones de pesos constantes de 2016 | Y7: Millones de pesos constantes de 2016 | Z7: Millones de pesos constantes de 2016
A8: CÓDIGO | B8: 1.1.1.1.1 | C8: 1.1.1.1.2 | D8: 1.1.1.1.3 | E8: 1.1.1.1.4 | F8: 1.1.1.1.5 | G8: 1.1.1.1.6 | H8: 1.1.1.1.7 | I8: 1.1.1.1.8 | J8: 1.1.1.1.9 | K8: 1.1.1.1.10 | L8: 1.1.1.1.11 | M8: 1.1.1.1.12 | N8: 1.1.1.1.13 | O8: 1.1.1.1.14 | P8: 1.1.1.1.15 | Q8: 1.1.1.1.16 | R8: 1.1.1.1.17 | S8: 1.1.1.1.18 | T8: 1.1.1.1.19 | U8: 1.1.1.1.20 | V8: 1.1.1.1.21 | W8: 1.1.1.1.22 | X8: 1.1.1.1.23 | Y8: 1.1.1.1.24 | Z8: 1.1.1.1.25
A9: Jurisdicción | B9: C.A.B.A. | C9: Buenos Aires | D9: Catamarca | E9: Córdoba | F9: Corrientes | G9: Chaco | H9: Chubut | I9: Entre Ríos | J9: Formosa | K9: Jujuy | L9: La Pampa | M9: La Rioja | N9: Mendoza | O9: Misiones | P9: Neuquén | Q9: Río Negro | R9: Salta | S9: San Juan | T9: San Luis | U9: Santa Cruz | V9: Santa Fe | W9: Santiago del Estero | X9: Tucumán | Y9: Tierra del Fuego | Z9: Total
A10: 1992 | B10: =+'[1]1.1.1.1'!B10/Deflactores!$B10*100 -> 35085.397 | C10: =+'[1]1.1.1.1'!C10/Deflactores!$B10*100 -> 52653.247 | D10: =+'[1]1.1.1.1'!D10/Deflactores!$B10*100 -> 328.40734 | E10: =+'[1]1.1.1.1'!E10/Deflactores!$B10*100 -> 12654.609 | F10: =+'[1]1.1.1.1'!F10/Deflactores!$B10*100 -> 1061.8454 | G10: =+'[1]1.1.1.1'!G10/Deflactores!$B10*100 -> 1155.2987 | H10: =+'[1]1.1.1.1'!H10/Deflactores!$B10*100 -> 879.83481 | I10: =+'[1]1.1.1.1'!I10/Deflactores!$B10*100 -> 3036.9396 | ... Y10: =+'[1]1.1.1.1'!Y10/Deflactores!$B10*100 -> 1044.0254 | Z10: =SUM(B10:Y10) -> 141370.88
A11: 1993 | B11: =+'[1]1.1.1.1'!B11/Deflactores!$B11*100 -> 41471.19 | C11: =+'[1]1.1.1.1'!C11/Deflactores!$B11*100 -> 56671.882 | D11: =+'[1]1.1.1.1'!D11/Deflactores!$B11*100 -> 409.08571 | E11: =+'[1]1.1.1.1'!E11/Deflactores!$B11*100 -> 13336.594 | F11: =+'[1]1.1.1.1'!F11/Deflactores!$B11*100 -> 1244.5607 | G11: =+'[1]1.1.1.1'!G11/Deflactores!$B11*100 -> 1254.8895 | H11: =+'[1]1.1.1.1'!H11/Deflactores!$B11*100 -> 875.53205 | I11: =+'[1]1.1.1.1'!I11/Deflactores!$B11*100 -> 3635.9365 | ... Y11: =+'[1]1.1.1.1'!Y11/Deflactores!$B11*100 -> 1098.9494 | Z11: =SUM(B11:Y11) -> 156289.06
A12: 1994 | B12: =+'[1]1.1.1.1'!B12/Deflactores!$B12*100 -> 40788.277 | C12: =+'[1]1.1.1.1'!C12/Deflactores!$B12*100 -> 63135.446 | D12: =+'[1]1.1.1.1'!D12/Deflactores!$B12*100 -> 456.12767 | E12: =+'[1]1.1.1.1'!E12/Deflactores!$B12*100 -> 14912.498 | F12: =+'[1]1.1.1.1'!F12/Deflactores!$B12*100 -> 1227.0036 | G12: =+'[1]1.1.1.1'!G12/Deflactores!$B12*100 -> 1405.9753 | H12: =+'[1]1.1.1.1'!H12/Deflactores!$B12*100 -> 905.02645 | I12: =+'[1]1.1.1.1'!I12/Deflactores!$B12*100 -> 4306.801 | ... Y12: =+'[1]1.1.1.1'!Y12/Deflactores!$B12*100 -> 842.13354 | Z12: =SUM(B12:Y12) -> 167908.47
A13: 1995 | B13: =+'[1]1.1.1.1'!B13/Deflactores!$B13*100 -> 37714.326 | C13: =+'[1]1.1.1.1'!C13/Deflactores!$B13*100 -> 57102.771 | D13: =+'[1]1.1.1.1'!D13/Deflactores!$B13*100 -> 365.40618 | E13: =+'[1]1.1.1.1'!E13/Deflactores!$B13*100 -> 13963.242 | F13: =+'[1]1.1.1.1'!F13/Deflactores!$B13*100 -> 1140.8703 | G13: =+'[1]1.1.1.1'!G13/Deflactores!$B13*100 -> 1619.7511 | H13: =+'[1]1.1.1.1'!H13/Deflactores!$B13*100 -> 867.60351 | I13: =+'[1]1.1.1.1'!I13/Deflactores!$B13*100 -> 4409.973 | ... Y13: =+'[1]1.1.1.1'!Y13/Deflactores!$B13*100 -> 729.10447 | Z13: =SUM(B13:Y13) -> 151006.83
A14: 1996 | B14: =+'[1]1.1.1.1'!B14/Deflactores!$B14*100 -> 37798.219 | C14: =+'[1]1.1.1.1'!C14/Deflactores!$B14*100 -> 63184.04 | D14: =+'[1]1.1.1.1'!D14/Deflactores!$B14*100 -> 585.52044 | E14: =+'[1]1.1.1.1'!E14/Deflactores!$B14*100 -> 14107.232 | F14: =+'[1]1.1.1.1'!F14/Deflactores!$B14*100 -> 1099.8901 | G14: =+'[1]1.1.1.1'!G14/Deflactores!$B14*100 -> 1799.6117 | H14: =+'[1]1.1.1.1'!H14/Deflactores!$B14*100 -> 923.28313 | I14: =+'[1]1.1.1.1'!I14/Deflactores!$B14*100 -> 4673.9693 | ... Y14: =+'[1]1.1.1.1'!Y14/Deflactores!$B14*100 -> 646.66182 | Z14: =SUM(B14:Y14) -> 160118.76
A15: 1997 | B15: =+'[1]1.1.1.1'!B15/Deflactores!$B15*100 -> 41453.782 | C15: =+'[1]1.1.1.1'!C15/Deflactores!$B15*100 -> 76132.346 | D15: =+'[1]1.1.1.1'!D15/Deflactores!$B15*100 -> 653.10396 | E15: =+'[1]1.1.1.1'!E15/Deflactores!$B15*100 -> 14343.929 | F15: =+'[1]1.1.1.1'!F15/Deflactores!$B15*100 -> 1224.8828 | G15: =+'[1]1.1.1.1'!G15/Deflactores!$B15*100 -> 1890.277 | H15: =+'[1]1.1.1.1'!H15/Deflactores!$B15*100 -> 1048.8018 | I15: =+'[1]1.1.1.1'!I15/Deflactores!$B15*100 -> 5037.6064 | ... Y15: =+'[1]1.1.1.1'!Y15/Deflactores!$B15*100 -> 700.89593 | Z15: =SUM(B15:Y15) -> 183946.56
A16: 1998 | B16: =+'[1]1.1.1.1'!B16/Deflactores!$B16*100 -> 48559.005 | C16: =+'[1]1.1.1.1'!C16/Deflactores!$B16*100 -> 82664.636 | D16: =+'[1]1.1.1.1'!D16/Deflactores!$B16*100 -> 708.76191 | E16: =+'[1]1.1.1.1'!E16/Deflactores!$B16*100 -> 15976.882 | F16: =+'[1]1.1.1.1'!F16/Deflactores!$B16*100 -> 1327.7775 | G16: =+'[1]1.1.1.1'!G16/Deflactores!$B16*100 -> 1835.469 | H16: =+'[1]1.1.1.1'!H16/Deflactores!$B16*100 -> 1053.2634 | I16: =+'[1]1.1.1.1'!I16/Deflactores!$B16*100 -> 5306.1148 | ... Y16: =+'[1]1.1.1.1'!Y16/Deflactores!$B16*100 -> 778.21687 | Z16: =SUM(B16:Y16) -> 204276.28
A17: 1999 | B17: =+'[1]1.1.1.1'!B17/Deflactores!$B17*100 -> 50019.873 | C17: =+'[1]1.1.1.1'!C17/Deflactores!$B17*100 -> 79506.014 | D17: =+'[1]1.1.1.1'!D17/Deflactores!$B17*100 -> 714.78724 | E17: =+'[1]1.1.1.1'!E17/Deflactores!$B17*100 -> 15282.412 | F17: =+'[1]1.1.1.1'!F17/Deflactores!$B17*100 -> 1236.1225 | G17: =+'[1]1.1.1.1'!G17/Deflactores!$B17*100 -> 1828.9545 | H17: =+'[1]1.1.1.1'!H17/Deflactores!$B17*100 -> 1190.6787 | I17: =+'[1]1.1.1.1'!I17/Deflactores!$B17*100 -> 5193.4245 | ... Y17: =+'[1]1.1.1.1'!Y17/Deflactores!$B17*100 -> 814.65361 | Z17: =SUM(B17:Y17) -> 202127.56
A18: 2000 | B18: =+'[1]1.1.1.1'!B18/Deflactores!$B18*100 -> 52444.692 | C18: =+'[1]1.1.1.1'!C18/Deflactores!$B18*100 -> 79270.473 | D18: =+'[1]1.1.1.1'!D18/Deflactores!$B18*100 -> 735.12017 | E18: =+'[1]1.1.1.1'!E18/Deflactores!$B18*100 -> 16263.134 | F18: =+'[1]1.1.1.1'!F18/Deflactores!$B18*100 -> 1482.4468 | G18: =+'[1]1.1.1.1'!G18/Deflactores!$B18*100 -> 1761.651 | H18: =+'[1]1.1.1.1'!H18/Deflactores!$B18*100 -> 1376.2016 | I18: =+'[1]1.1.1.1'!I18/Deflactores!$B18*100 -> 4986.9274 | ... Y18: =+'[1]1.1.1.1'!Y18/Deflactores!$B18*100 -> 830.87694 | Z18: =SUM(B18:Y18) -> 206967.99
A19: 2001 | B19: =+'[1]1.1.1.1'!B19/Deflactores!$B19*100 -> 49110.248 | C19: =+'[1]1.1.1.1'!C19/Deflactores!$B19*100 -> 70332.41 | D19: =+'[1]1.1.1.1'!D19/Deflactores!$B19*100 -> 713.33998 | E19: =+'[1]1.1.1.1'!E19/Deflactores!$B19*100 -> 14714.842 | F19: =+'[1]1.1.1.1'!F19/Deflactores!$B19*100 -> 1542.8818 | G19: =+'[1]1.1.1.1'!G19/Deflactores!$B19*100 -> 1568.0121 | H19: =+'[1]1.1.1.1'!H19/Deflactores!$B19*100 -> 1568.4665 | I19: =+'[1]1.1.1.1'!I19/Deflactores!$B19*100 -> 5059.4529 | ... Y19: =+'[1]1.1.1.1'!Y19/Deflactores!$B19*100 -> 899.81085 | Z19: =SUM(B19:Y19) -> 190879.99
A20: 2002 | B20: =+'[1]1.1.1.1'!B20/Deflactores!$B20*100 -> 33055.26 | C20: =+'[1]1.1.1.1'!C20/Deflactores!$B20*100 -> 57191.523 | D20: =+'[1]1.1.1.1'!D20/Deflactores!$B20*100 -> 472.58508 | E20: =+'[1]1.1.1.1'!E20/Deflactores!$B20*100 -> 10777.478 | F20: =+'[1]1.1.1.1'!F20/Deflactores!$B20*100 -> 1059.7544 | G20: =+'[1]1.1.1.1'!G20/Deflactores!$B20*100 -> 1320.5748 | H20: =+'[1]1.1.1.1'!H20/Deflactores!$B20*100 -> 1424.4549 | I20: =+'[1]1.1.1.1'!I20/Deflactores!$B20*100 -> 3343.9128 | ... Y20: =+'[1]1.1.1.1'!Y20/Deflactores!$B20*100 -> 620.84779 | Z20: =SUM(B20:Y20) -> 142662.23
A21: 2003 | B21: =+'[1]1.1.1.1'!B21/Deflactores!$B21*100 -> 36552.313 | C21: =+'[1]1.1.1.1'!C21/Deflactores!$B21*100 -> 63311.892 | D21: =+'[1]1.1.1.1'!D21/Deflactores!$B21*100 -> 644.42946 | E21: =+'[1]1.1.1.1'!E21/Deflactores!$B21*100 -> 11576.633 | F21: =+'[1]1.1.1.1'!F21/Deflactores!$B21*100 -> 1066.2633 | G21: =+'[1]1.1.1.1'!G21/Deflactores!$B21*100 -> 1563.0045 | H21: =+'[1]1.1.1.1'!H21/Deflactores!$B21*100 -> 1630.5524 | I21: =+'[1]1.1.1.1'!I21/Deflactores!$B21*100 -> 3662.096 | ... Y21: =+'[1]1.1.1.1'!Y21/Deflactores!$B21*100 -> 892.7015 | Z21: =SUM(B21:Y21) -> 160141.56
... A48: 2030 | B48: =+'[1]1.1.1.1'!B48/Deflactores!$B48*100 -> #N/A | C48: =+'[1]1.1.1.1'!C48/Deflactores!$B48*100 -> #N/A | D48: =+'[1]1.1.1.1'!D48/Deflactores!$B48*100 -> #N/A | E48: =+'[1]1.1.1.1'!E48/Deflactores!$B48*100 -> #N/A | F48: =+'[1]1.1.1.1'!F48/Deflactores!$B48*100 -> #N/A | G48: =+'[1]1.1.1.1'!G48/Deflactores!$B48*100 -> #N/A | H48: =+'[1]1.1.1.1'!H48/Deflactores!$B48*100 -> #N/A | I48: =+'[1]1.1.1.1'!I48/Deflactores!$B48*100 -> #N/A | ... Y48: =+'[1]1.1.1.1'!Y48/Deflactores!$B48*100 -> #N/A | Z48: =SUM(B48:Y48) -> #N/A

Sheet 1.1.1.1.1
A2: Título | B2: Ingresos Brutos | N2: =B2 -> Ingresos Brutos
A3: Fuente | B3: Dirección Nacional de Asuntos Provinciales - Ministerio de Economía de la Nación | N3: =B3 -> Dirección Nacional de Asuntos Provinciales - Ministerio de Economía de la Nación
A5: VOLVER AL ÍNDICE | B5: Administración Pública No Financiera | N5: =B5 -> Administración Pública No Financiera
A7: Unidad de medida | B7: Millones de pesos constantes de 2016 | C7: Millones de pesos constantes de 2016 | D7: Millones de pesos constantes de 2016 | E7: Millones de pesos constantes de 2016 | F7: Millones de pesos constantes de 2016 | G7: Millones de pesos constantes de 2016 | H7: Millones de pesos constantes de 2016 | I7: Millones de pesos constantes de 2016 | J7: Millones de pesos constantes de 2016 | K7: Millones de pesos constantes de 2016 | L7: Millones de pesos constantes de 2016 | M7: Millones de pesos constantes de 2016 | N7: Millones de pesos constantes de 2016 | O7: Millones de pesos constantes de 2016 | P7: Millones de pesos constantes de 2016 | Q7: Millones de pesos constantes de 2016 | R7: Millones de pesos constantes de 2016 | S7: Millones de pesos constantes de 2016 | T7: Millones de pesos constantes de 2016 | U7: Millones de pesos constantes de 2016 | V7: Millones de pesos constantes de 2016 | W7: Millones de pesos constantes de 2016 | X7: Millones de pesos constantes de 2016 | Y7: Millones de pesos constantes de 2016 | Z7: Millones de pesos constantes de 2016
A8: CÓDIGO | B8: 1.1.1.1.1.1 | C8: 1.1.1.1.1.2 | D8: 1.1.1.1.1.3 | E8: 1.1.1.1.1.4 | F8: 1.1.1.1.1.5 | G8: 1.1.1.1.1.6 | H8: 1.1.1.1.1.7 | I8: 1.1.1.1.1.8 | J8: 1.1.1.1.1.9 | K8: 1.1.1.1.1.10 | L8: 1.1.1.1.1.11 | M8: 1.1.1.1.1.12 | N8: 1.1.1.1.1.13 | O8: 1.1.1.1.1.14 | P8: 1.1.1.1.1.15 | Q8: 1.1.1.1.1.16 | R8: 1.1.1.1.1.17 | S8: 1.1.1.1.1.18 | T8: 1.1.1.1.1.19 | U8: 1.1.1.1.1.20 | V8: 1.1.1.1.1.21 | W8: 1.1.1.1.1.22 | X8: 1.1.1.1.1.23 | Y8: 1.1.1.1.1.24 | Z8: 1.1.1.1.1.25
A9: Jurisdicción | B9: C.A.B.A. | C9: Buenos Aires | D9: Catamarca | E9: Córdoba | F9: Corrientes | G9: Chaco | H9: Chubut | I9: Entre Ríos | J9: Formosa | K9: Jujuy | L9: La Pampa | M9: La Rioja | N9: Mendoza | O9: Misiones | P9: Neuquén | Q9: Río Negro | R9: Salta | S9: San Juan | T9: San Luis | U9: Santa Cruz | V9: Santa Fe | W9: Santiago del Estero | X9: Tucumán | Y9: Tierra del Fuego | Z9: Total
A10: 1992 | B10: =+'[1]1.1.1.1.1'!B10/Deflactores!$B10*100 -> 22889.715 | C10: =+'[1]1.1.1.1.1'!C10/Deflactores!$B10*100 -> 24767.13 | D10: =+'[1]1.1.1.1.1'!D10/Deflactores!$B10*100 -> 200.87518 | E10: =+'[1]1.1.1.1.1'!E10/Deflactores!$B10*100 -> 6868.3848 | F10: =+'[1]1.1.1.1.1'!F10/Deflactores!$B10*100 -> 698.16005 | G10: =+'[1]1.1.1.1.1'!G10/Deflactores!$B10*100 -> 784.71754 | H10: =+'[1]1.1.1.1.1'!H10/Deflactores!$B10*100 -> 645.90082 | I10: =+'[1]1.1.1.1.1'!I10/Deflactores!$B10*100 -> 1187.6183 | ... Y10: =+'[1]1.1.1.1.1'!Y10/Deflactores!$B10*100 -> 579.70488 | Z10: =SUM(B10:Y10) -> 77959.141
A11: 1993 | B11: =+'[1]1.1.1.1.1'!B11/Deflactores!$B11*100 -> 29341.267 | C11: =+'[1]1.1.1.1.1'!C11/Deflactores!$B11*100 -> 26629.748 | D11: =+'[1]1.1.1.1.1'!D11/Deflactores!$B11*100 -> 250.22323 | E11: =+'[1]1.1.1.1.1'!E11/Deflactores!$B11*100 -> 7473.2091 | F11: =+'[1]1.1.1.1.1'!F11/Deflactores!$B11*100 -> 831.9219 | G11: =+'[1]1.1.1.1.1'!G11/Deflactores!$B11*100 -> 821.57031 | H11: =+'[1]1.1.1.1.1'!H11/Deflactores!$B11*100 -> 658.55391 | I11: =+'[1]1.1.1.1.1'!I11/Deflactores!$B11*100 -> 1421.8606 | ... Y11: =+'[1]1.1.1.1.1'!Y11/Deflactores!$B11*100 -> 674.85019 | Z11: =SUM(B11:Y11) -> 89268.518
A12: 1994 | B12: =+'[1]1.1.1.1.1'!B12/Deflactores!$B12*100 -> 27070.881 | C12: =+'[1]1.1.1.1.1'!C12/Deflactores!$B12*100 -> 31281.118 | D12: =+'[1]1.1.1.1.1'!D12/Deflactores!$B12*100 -> 265.37428 | E12: =+'[1]1.1.1.1.1'!E12/Deflactores!$B12*100 -> 8686.8613 | F12: =+'[1]1.1.1.1.1'!F12/Deflactores!$B12*100 -> 825.82667 | G12: =+'[1]1.1.1.1.1'!G12/Deflactores!$B12*100 -> 965.50768 | H12: =+'[1]1.1.1.1.1'!H12/Deflactores!$B12*100 -> 673.49603 | I12: =+'[1]1.1.1.1.1'!I12/Deflactores!$B12*100 -> 1684.2073 | ... Y12: =+'[1]1.1.1.1.1'!Y12/Deflactores!$B12*100 -> 715.59673 | Z12: =SUM(B12:Y12) -> 95513.963
A13: 1995 | B13: =+'[1]1.1.1.1.1'!B13/Deflactores!$B13*100 -> 24963.35 | C13: =+'[1]1.1.1.1.1'!C13/Deflactores!$B13*100 -> 28292.166 | D13: =+'[1]1.1.1.1.1'!D13/Deflactores!$B13*100 -> 232.94969 | E13: =+'[1]1.1.1.1.1'!E13/Deflactores!$B13*100 -> 7824.3575 | F13: =+'[1]1.1.1.1.1'!F13/Deflactores!$B13*100 -> 652.99409 | G13: =+'[1]1.1.1.1.1'!G13/Deflactores!$B13*100 -> 1184.9175 | H13: =+'[1]1.1.1.1.1'!H13/Deflactores!$B13*100 -> 644.79931 | I13: =+'[1]1.1.1.1.1'!I13/Deflactores!$B13*100 -> 1587.4932 | ... Y13: =+'[1]1.1.1.1.1'!Y13/Deflactores!$B13*100 -> 713.44481 | Z13: =SUM(B13:Y13) -> 85953.571
A14: 1996 | B14: =+'[1]1.1.1.1.1'!B14/Deflactores!$B14*100 -> 23739.011 | C14: =+'[1]1.1.1.1.1'!C14/Deflactores!$B14*100 -> 31305.194 | D14: =+'[1]1.1.1.1.1'!D14/Deflactores!$B14*100 -> 404.45859 | E14: =+'[1]1.1.1.1.1'!E14/Deflactores!$B14*100 -> 7905.0391 | F14: =+'[1]1.1.1.1.1'!F14/Deflactores!$B14*100 -> 764.7805 | G14: =+'[1]1.1.1.1.1'!G14/Deflactores!$B14*100 -> 1168.9625 | H14: =+'[1]1.1.1.1.1'!H14/Deflactores!$B14*100 -> 686.18015 | I14: =+'[1]1.1.1.1.1'!I14/Deflactores!$B14*100 -> 2229.4172 | ... Y14: =+'[1]1.1.1.1.1'!Y14/Deflactores!$B14*100 -> 635.10646 | Z14: =SUM(B14:Y14) -> 89632.242
A15: 1997 | B15: =+'[1]1.1.1.1.1'!B15/Deflactores!$B15*100 -> 26875.005 | C15: =+'[1]1.1.1.1.1'!C15/Deflactores!$B15*100 -> 35678.7 | D15: =+'[1]1.1.1.1.1'!D15/Deflactores!$B15*100 -> 496.14873 | E15: =+'[1]1.1.1.1.1'!E15/Deflactores!$B15*100 -> 7787.3429 | F15: =+'[1]1.1.1.1.1'!F15/Deflactores!$B15*100 -> 862.50796 | G15: =+'[1]1.1.1.1.1'!G15/Deflactores!$B15*100 -> 1296.1283 | H15: =+'[1]1.1.1.1.1'!H15/Deflactores!$B15*100 -> 823.81429 | I15: =+'[1]1.1.1.1.1'!I15/Deflactores!$B15*100 -> 2491.1666 | ... Y15: =+'[1]1.1.1.1.1'!Y15/Deflactores!$B15*100 -> 669.22955 | Z15: =SUM(B15:Y15) -> 101460.4
A16: 1998 | B16: =+'[1]1.1.1.1.1'!B16/Deflactores!$B16*100 -> 32733.853 | C16: =+'[1]1.1.1.1.1'!C16/Deflactores!$B16*100 -> 39855.883 | D16: =+'[1]1.1.1.1.1'!D16/Deflactores!$B16*100 -> 487.6928 | E16: =+'[1]1.1.1.1.1'!E16/Deflactores!$B16*100 -> 8757.3461 | F16: =+'[1]1.1.1.1.1'!F16/Deflactores!$B16*100 -> 941.05508 | G16: =+'[1]1.1.1.1.1'!G16/Deflactores!$B16*100 -> 1561.2169 | H16: =+'[1]1.1.1.1.1'!H16/Deflactores!$B16*100 -> 789.29973 | I16: =+'[1]1.1.1.1.1'!I16/Deflactores!$B16*100 -> 2539.7195 | ... Y16: =+'[1]1.1.1.1.1'!Y16/Deflactores!$B16*100 -> 754.67809 | Z16: =SUM(B16:Y16) -> 114829.72
A17: 1999 | B17: =+'[1]1.1.1.1.1'!B17/Deflactores!$B17*100 -> 34510.697 | C17: =+'[1]1.1.1.1.1'!C17/Deflactores!$B17*100 -> 38723.708 | D17: =+'[1]1.1.1.1.1'!D17/Deflactores!$B17*100 -> 497.44152 | E17: =+'[1]1.1.1.1.1'!E17/Deflactores!$B17*100 -> 8316.0878 | F17: =+'[1]1.1.1.1.1'!F17/Deflactores!$B17*100 -> 890.60568 | G17: =+'[1]1.1.1.1.1'!G17/Deflactores!$B17*100 -> 1582.2285 | H17: =+'[1]1.1.1.1.1'!H17/Deflactores!$B17*100 -> 878.59124 | I17: =+'[1]1.1.1.1.1'!I17/Deflactores!$B17*100 -> 2566.7575 | ... Y17: =+'[1]1.1.1.1.1'!Y17/Deflactores!$B17*100 -> 730.57735 | Z17: =SUM(B17:Y17) -> 114244.37
A18: 2000 | B18: =+'[1]1.1.1.1.1'!B18/Deflactores!$B18*100 -> 35736.929 | C18: =+'[1]1.1.1.1.1'!C18/Deflactores!$B18*100 -> 38678.018 | D18: =+'[1]1.1.1.1.1'!D18/Deflactores!$B18*100 -> 482.68986 | E18: =+'[1]1.1.1.1.1'!E18/Deflactores!$B18*100 -> 7723.3759 | F18: =+'[1]1.1.1.1.1'!F18/Deflactores!$B18*100 -> 1029.748 | G18: =+'[1]1.1.1.1.1'!G18/Deflactores!$B18*100 -> 1544.9679 | H18: =+'[1]1.1.1.1.1'!H18/Deflactores!$B18*100 -> 1048.4589 | I18: =+'[1]1.1.1.1.1'!I18/Deflactores!$B18*100 -> 2321.6063 | ... Y18: =+'[1]1.1.1.1.1'!Y18/Deflactores!$B18*100 -> 755.43436 | Z18: =SUM(B18:Y18) -> 116415.2
A19: 2001 | B19: =+'[1]1.1.1.1.1'!B19/Deflactores!$B19*100 -> 33315.373 | C19: =+'[1]1.1.1.1.1'!C19/Deflactores!$B19*100 -> 34979.141 | D19: =+'[1]1.1.1.1.1'!D19/Deflactores!$B19*100 -> 489.88985 | E19: =+'[1]1.1.1.1.1'!E19/Deflactores!$B19*100 -> 7843.8098 | F19: =+'[1]1.1.1.1.1'!F19/Deflactores!$B19*100 -> 1042.3253 | G19: =+'[1]1.1.1.1.1'!G19/Deflactores!$B19*100 -> 1333.0845 | H19: =+'[1]1.1.1.1.1'!H19/Deflactores!$B19*100 -> 1075.0858 | I19: =+'[1]1.1.1.1.1'!I19/Deflactores!$B19*100 -> 2218.2715 | ... Y19: =+'[1]1.1.1.1.1'!Y19/Deflactores!$B19*100 -> 770.42287 | Z19: =SUM(B19:Y19) -> 109210.93
A20: 2002 | B20: =+'[1]1.1.1.1.1'!B20/Deflactores!$B20*100 -> 23111.713 | C20: =+'[1]1.1.1.1.1'!C20/Deflactores!$B20*100 -> 28074.817 | D20: =+'[1]1.1.1.1.1'!D20/Deflactores!$B20*100 -> 342.22634 | E20: =+'[1]1.1.1.1.1'!E20/Deflactores!$B20*100 -> 5789.9976 | F20: =+'[1]1.1.1.1.1'!F20/Deflactores!$B20*100 -> 784.5837 | G20: =+'[1]1.1.1.1.1'!G20/Deflactores!$B20*100 -> 1112.631 | H20: =+'[1]1.1.1.1.1'!H20/Deflactores!$B20*100 -> 1142.3517 | I20: =+'[1]1.1.1.1.1'!I20/Deflactores!$B20*100 -> 1641.5307 | ... Y20: =+'[1]1.1.1.1.1'!Y20/Deflactores!$B20*100 -> 575.42495 | Z20: =SUM(B20:Y20) -> 82776.004
A21: 2003 | B21: =+'[1]1.1.1.1.1'!B21/Deflactores!$B21*100 -> 25305.895 | C21: =+'[1]1.1.1.1.1'!C21/Deflactores!$B21*100 -> 34614.318 | D21: =+'[1]1.1.1.1.1'!D21/Deflactores!$B21*100 -> 467.24669 | E21: =+'[1]1.1.1.1.1'!E21/Deflactores!$B21*100 -> 6954.2275 | F21: =+'[1]1.1.1.1.1'!F21/Deflactores!$B21*100 -> 754.58443 | G21: =+'[1]1.1.1.1.1'!G21/Deflactores!$B21*100 -> 1310.4643 | H21: =+'[1]1.1.1.1.1'!H21/Deflactores!$B21*100 -> 1299.5696 | I21: =+'[1]1.1.1.1.1'!I21/Deflactores!$B21*100 -> 1785.3952 | ... Y21: =+'[1]1.1.1.1.1'!Y21/Deflactores!$B21*100 -> 744.42318 | Z21: =SUM(B21:Y21) -> 98960.113
... A48: 2030 | B48: =+'[1]1.1.1.1.1'!B48/Deflactores!$B48*100 -> #N/A | C48: =+'[1]1.1.1.1.1'!C48/Deflactores!$B48*100 -> #N/A | D48: =+'[1]1.1.1.1.1'!D48/Deflactores!$B48*100 -> #N/A | E48: =+'[1]1.1.1.1.1'!E48/Deflactores!$B48*100 -> #N/A | F48: =+'[1]1.1.1.1.1'!F48/Deflactores!$B48*100 -> #N/A | G48: =+'[1]1.1.1.1.1'!G48/Deflactores!$B48*100 -> #N/A | H48: =+'[1]1.1.1.1.1'!H48/Deflactores!$B48*100 -> #N/A | I48: =+'[1]1.1.1.1.1'!I48/Deflactores!$B48*100 -> #N/A | ... Y48: =+'[1]1.1.1.1.1'!Y48/Deflactores!$B48*100 -> #N/A | Z48: =SUM(B48:Y48) -> #N/A

Sheet 1.1.1.1.2
A2: Título | B2: Inmobiliario | N2: =B2 -> Inmobiliario
A3: Fuente | B3: Dirección Nacional de Asuntos Provinciales - Ministerio de Economía de la Nación | N3: =B3 -> Dirección Nacional de Asuntos Provinciales - Ministerio de Economía de la Nación
A5: VOLVER AL ÍNDICE | B5: Administración Pública No Financiera | N5: =B5 -> Administración Pública No Financiera
A7: Unidad de medida | B7: Millones de pesos constantes de 2016 | C7: Millones de pesos constantes de 2016 | D7: Millones de pesos constantes de 2016 | E7: Millones de pesos constantes de 2016 | F7: Millones de pesos constantes de 2016 | G7: Millones de pesos constantes de 2016 | H7: Millones de pesos constantes de 2016 | I7: Millones de pesos constantes de 2016 | J7: Millones de pesos constantes de 2016 | K7: Millones de pesos constantes de 2016 | L7: Millones de pesos constantes de 2016 | M7: Millones de pesos constantes de 2016 | N7: Millones de pesos constantes de 2016 | O7: Millones de pesos constantes de 2016 | P7: Millones de pesos constantes de 2016 | Q7: Millones de pesos constantes de 2016 | R7: Millones de pesos constantes de 2016 | S7: Millones de pesos constantes de 2016 | T7: Millones de pesos constantes de 2016 | U7: Millones de pesos constantes de 2016 | V7: Millones de pesos constantes de 2016 | W7: Millones de pesos constantes de 2016 | X7: Millones de pesos constantes de 2016 | Y7: Millones de pesos constantes de 2016 | Z7: Millones de pesos constantes de 2016
A8: CÓDIGO | B8: 1.1.1.1.2.1 | C8: 1.1.1.1.2.2 | D8: 1.1.1.1.2.3 | E8: 1.1.1.1.2.4 | F8: 1.1.1.1.2.5 | G8: 1.1.1.1.2.6 | H8: 1.1.1.1.2.7 | I8: 1.1.1.1.2.8 | J8: 1.1.1.1.2.9 | K8: 1.1.1.1.2.10 | L8: 1.1.1.1.2.11 | M8: 1.1.1.1.2.12 | N8: 1.1.1.1.2.13 | O8: 1.1.1.1.2.14 | P8: 1.1.1.1.2.15 | Q8: 1.1.1.1.2.16 | R8: 1.1.1.1.2.17 | S8: 1.1.1.1.2.18 | T8: 1.1.1.1.2.19 | U8: 1.1.1.1.2.20 | V8: 1.1.1.1.2.21 | W8: 1.1.1.1.2.22 | X8: 1.1.1.1.2.23 | Y8: 1.1.1.1.2.24 | Z8: 1.1.1.1.2.25
A9: Jurisdicción | B9: C.A.B.A. | C9: Buenos Aires | D9: Catamarca | E9: Córdoba | F9: Corrientes | G9: Chaco | H9: Chubut | I9: Entre Ríos | J9: Formosa | K9: Jujuy | L9: La Pampa | M9: La Rioja | N9: Mendoza | O9: Misiones | P9: Neuquén | Q9: Río Negro | R9: Salta | S9: San Juan | T9: San Luis | U9: Santa Cruz | V9: Santa Fe | W9: Santiago del Estero | X9: Tucumán | Y9: Tierra del Fuego | Z9: Total
A10: 1992 | B10: =+'[1]1.1.1.1.2'!B10/Deflactores!$B10*100 -> 7395.9988 | C10: =+'[1]1.1.1.1.2'!C10/Deflactores!$B10*100 -> 8844.5825 | D10: =+'[1]1.1.1.1.2'!D10/Deflactores!$B10*100 -> 32.062545 | E10: =+'[1]1.1.1.1.2'!E10/Deflactores!$B10*100 -> 3979.3607 | F10: =+'[1]1.1.1.1.2'!F10/Deflactores!$B10*100 -> 193.26503 | G10: =+'[1]1.1.1.1.2'!G10/Deflactores!$B10*100 -> 28.961253 | H10: =+'[1]1.1.1.1.2'!H10/Deflactores!$B10*100 -> 2.1077037 | I10: =+'[1]1.1.1.1.2'!I10/Deflactores!$B10*100 -> 831.77276 | ... Y10: =+'[1]1.1.1.1.2'!Y10/Deflactores!$B10*100 -> 1.266695 | Z10: =SUM(B10:Y10) -> 26568.457
A11: 1993 | B11: =+'[1]1.1.1.1.2'!B11/Deflactores!$B11*100 -> 6810.7441 | C11: =+'[1]1.1.1.1.2'!C11/Deflactores!$B11*100 -> 9524.8092 | D11: =+'[1]1.1.1.1.2'!D11/Deflactores!$B11*100 -> 39.939287 | E11: =+'[1]1.1.1.1.2'!E11/Deflactores!$B11*100 -> 3792.6706 | F11: =+'[1]1.1.1.1.2'!F11/Deflactores!$B11*100 -> 208.45659 | G11: =+'[1]1.1.1.1.2'!G11/Deflactores!$B11*100 -> 27.51482 | H11: =+'[1]1.1.1.1.2'!H11/Deflactores!$B11*100 -> 2.021001 | I11: =+'[1]1.1.1.1.2'!I11/Deflactores!$B11*100 -> 995.82924 | ... Y11: =+'[1]1.1.1.1.2'!Y11/Deflactores!$B11*100 -> 1.1076777 | Z11: =SUM(B11:Y11) -> 26515.719
A12: 1994 | B12: =+'[1]1.1.1.1.2'!B12/Deflactores!$B12*100 -> 7216.1193 | C12: =+'[1]1.1.1.1.2'!C12/Deflactores!$B12*100 -> 9670.0535 | D12: =+'[1]1.1.1.1.2'!D12/Deflactores!$B12*100 -> 59.661606 | E12: =+'[1]1.1.1.1.2'!E12/Deflactores!$B12*100 -> 4036.9759 | F12: =+'[1]1.1.1.1.2'!F12/Deflactores!$B12*100 -> 175.65261 | G12: =+'[1]1.1.1.1.2'!G12/Deflactores!$B12*100 -> 47.464262 | H12: =+'[1]1.1.1.1.2'!H12/Deflactores!$B12*100 -> 1.8739542 | I12: =+'[1]1.1.1.1.2'!I12/Deflactores!$B12*100 -> 1179.5691 | ... Y12: =+'[1]1.1.1.1.2'!Y12/Deflactores!$B12*100 -> 1.5657312 | Z12: =SUM(B12:Y12) -> 28592.317
A13: 1995 | B13: =+'[1]1.1.1.1.2'!B13/Deflactores!$B13*100 -> 6700.1066 | C13: =+'[1]1.1.1.1.2'!C13/Deflactores!$B13*100 -> 8746.0671 | D13: =+'[1]1.1.1.1.2'!D13/Deflactores!$B13*100 -> 38.56264 | E13: =+'[1]1.1.1.1.2'!E13/Deflactores!$B13*100 -> 3970.8792 | F13: =+'[1]1.1.1.1.2'!F13/Deflactores!$B13*100 -> 143.65853 | G13: =+'[1]1.1.1.1.2'!G13/Deflactores!$B13*100 -> 51.168127 | H13: =+'[1]1.1.1.1.2'!H13/Deflactores!$B13*100 -> 10.671881 | I13: =+'[1]1.1.1.1.2'!I13/Deflactores!$B13*100 -> 1232.0944 | ... Y13: =+'[1]1.1.1.1.2'!Y13/Deflactores!$B13*100 -> 1.1971434 | Z13: =SUM(B13:Y13) -> 25739.244
A14: 1996 | B14: =+'[1]1.1.1.1.2'!B14/Deflactores!$B14*100 -> 6400.4125 | C14: =+'[1]1.1.1.1.2'!C14/Deflactores!$B14*100 -> 9677.4962 | D14: =+'[1]1.1.1.1.2'!D14/Deflactores!$B14*100 -> 68.494437 | E14: =+'[1]1.1.1.1.2'!E14/Deflactores!$B14*100 -> 4011.8254 | F14: =+'[1]1.1.1.1.2'!F14/Deflactores!$B14*100 -> 145.00352 | G14: =+'[1]1.1.1.1.2'!G14/Deflactores!$B14*100 -> 50.479241 | H14: =+'[1]1.1.1.1.2'!H14/Deflactores!$B14*100 -> 11.356714 | I14: =+'[1]1.1.1.1.2'!I14/Deflactores!$B14*100 -> 1080.9695 | ... Y14: =+'[1]1.1.1.1.2'!Y14/Deflactores!$B14*100 -> 0.95856274 | Z14: =SUM(B14:Y14) -> 26578.576
A15: 1997 | B15: =+'[1]1.1.1.1.2'!B15/Deflactores!$B15*100 -> 7595.6066 | C15: =+'[1]1.1.1.1.2'!C15/Deflactores!$B15*100 -> 11264.031 | D15: =+'[1]1.1.1.1.2'!D15/Deflactores!$B15*100 -> 59.25468 | E15: =+'[1]1.1.1.1.2'!E15/Deflactores!$B15*100 -> 4228.146 | F15: =+'[1]1.1.1.1.2'!F15/Deflactores!$B15*100 -> 173.71568 | G15: =+'[1]1.1.1.1.2'!G15/Deflactores!$B15*100 -> 45.065069 | H15: =+'[1]1.1.1.1.2'!H15/Deflactores!$B15*100 -> 1.1957889 | I15: =+'[1]1.1.1.1.2'!I15/Deflactores!$B15*100 -> 1066.5275 | ... Y15: =+'[1]1.1.1.1.2'!Y15/Deflactores!$B15*100 -> 2.3728408 | Z15: =SUM(B15:Y15) -> 30591.625
A16: 1998 | B16: =+'[1]1.1.1.1.2'!B16/Deflactores!$B16*100 -> 8418.1435 | C16: =+'[1]1.1.1.1.2'!C16/Deflactores!$B16*100 -> 11517.492 | D16: =+'[1]1.1.1.1.2'!D16/Deflactores!$B16*100 -> 66.834354 | E16: =+'[1]1.1.1.1.2'!E16/Deflactores!$B16*100 -> 5009.813 | F16: =+'[1]1.1.1.1.2'!F16/Deflactores!$B16*100 -> 131.08435 | G16: =+'[1]1.1.1.1.2'!G16/Deflactores!$B16*100 -> 38.137026 | H16: =+'[1]1.1.1.1.2'!H16/Deflactores!$B16*100 -> 1.8862571 | I16: =+'[1]1.1.1.1.2'!I16/Deflactores!$B16*100 -> 1171.8539 | ... Y16: =+'[1]1.1.1.1.2'!Y16/Deflactores!$B16*100 -> 1.1743098 | Z16: =SUM(B16:Y16) -> 32968.938
A17: 1999 | B17: =+'[1]1.1.1.1.2'!B17/Deflactores!$B17*100 -> 8754.916 | C17: =+'[1]1.1.1.1.2'!C17/Deflactores!$B17*100 -> 10818.038 | D17: =+'[1]1.1.1.1.2'!D17/Deflactores!$B17*100 -> 64.249424 | E17: =+'[1]1.1.1.1.2'!E17/Deflactores!$B17*100 -> 5023.1999 | F17: =+'[1]1.1.1.1.2'!F17/Deflactores!$B17*100 -> 123.2932 | G17: =+'[1]1.1.1.1.2'!G17/Deflactores!$B17*100 -> 35.847577 | H17: =+'[1]1.1.1.1.2'!H17/Deflactores!$B17*100 -> 0.98742267 | I17: =+'[1]1.1.1.1.2'!I17/Deflactores!$B17*100 -> 1140.9036 | ... Y17: =+'[1]1.1.1.1.2'!Y17/Deflactores!$B17*100 -> 1.5338161 | Z17: =SUM(B17:Y17) -> 32523.963
A18: 2000 | B18: =+'[1]1.1.1.1.2'!B18/Deflactores!$B18*100 -> 9644.6753 | C18: =+'[1]1.1.1.1.2'!C18/Deflactores!$B18*100 -> 11930.402 | D18: =+'[1]1.1.1.1.2'!D18/Deflactores!$B18*100 -> 83.881914 | E18: =+'[1]1.1.1.1.2'!E18/Deflactores!$B18*100 -> 3896.2348 | F18: =+'[1]1.1.1.1.2'!F18/Deflactores!$B18*100 -> 223.96061 | G18: =+'[1]1.1.1.1.2'!G18/Deflactores!$B18*100 -> 31.709642 | H18: =+'[1]1.1.1.1.2'!H18/Deflactores!$B18*100 -> 0.52703111 | I18: =+'[1]1.1.1.1.2'!I18/Deflactores!$B18*100 -> 1053.8248 | ... Y18: =+'[1]1.1.1.1.2'!Y18/Deflactores!$B18*100 -> 1.1471685 | Z18: =SUM(B18:Y18) -> 34452.501
A19: 2001 | B19: =+'[1]1.1.1.1.2'!B19/Deflactores!$B19*100 -> 9570.0283 | C19: =+'[1]1.1.1.1.2'!C19/Deflactores!$B19*100 -> 10849.243 | D19: =+'[1]1.1.1.1.2'!D19/Deflactores!$B19*100 -> 81.248817 | E19: =+'[1]1.1.1.1.2'!E19/Deflactores!$B19*100 -> 3388.1337 | F19: =+'[1]1.1.1.1.2'!F19/Deflactores!$B19*100 -> 243.51389 | G19: =+'[1]1.1.1.1.2'!G19/Deflactores!$B19*100 -> 33.010432 | H19: =+'[1]1.1.1.1.2'!H19/Deflactores!$B19*100 -> 0.055261474 | I19: =+'[1]1.1.1.1.2'!I19/Deflactores!$B19*100 -> 1167.8087 | ... Y19: =+'[1]1.1.1.1.2'!Y19/Deflactores!$B19*100 -> 1.0154052 | Z19: =SUM(B19:Y19) -> 32241.068
A20: 2002 | B20: =+'[1]1.1.1.1.2'!B20/Deflactores!$B20*100 -> 6241.1239 | C20: =+'[1]1.1.1.1.2'!C20/Deflactores!$B20*100 -> 8034.4744 | D20: =+'[1]1.1.1.1.2'!D20/Deflactores!$B20*100 -> 46.816044 | E20: =+'[1]1.1.1.1.2'!E20/Deflactores!$B20*100 -> 2316.6922 | F20: =+'[1]1.1.1.1.2'!F20/Deflactores!$B20*100 -> 143.45754 | G20: =+'[1]1.1.1.1.2'!G20/Deflactores!$B20*100 -> 32.23349 | H20: =+'[1]1.1.1.1.2'!H20/Deflactores!$B20*100 -> 0.26671628 | I20: =+'[1]1.1.1.1.2'!I20/Deflactores!$B20*100 -> 841.81177 | ... Y20: =+'[1]1.1.1.1.2'!Y20/Deflactores!$B20*100 -> 1.2264102 | Z20: =SUM(B20:Y20) -> 22735.209
A21: 2003 | B21: =+'[1]1.1.1.1.2'!B21/Deflactores!$B21*100 -> 6364.1897 | C21: =+'[1]1.1.1.1.2'!C21/Deflactores!$B21*100 -> 8976.1662 | D21: =+'[1]1.1.1.1.2'!D21/Deflactores!$B21*100 -> 63.01461 | E21: =+'[1]1.1.1.1.2'!E21/Deflactores!$B21*100 -> 3105.3382 | F21: =+'[1]1.1.1.1.2'!F21/Deflactores!$B21*100 -> 311.67895 | G21: =+'[1]1.1.1.1.2'!G21/Deflactores!$B21*100 -> 47.498327 | H21: =+'[1]1.1.1.1.2'!H21/Deflactores!$B21*100 -> 0.25656698 | I21: =+'[1]1.1.1.1.2'!I21/Deflactores!$B21*100 -> 940.51803 | ... Y21: =+'[1]1.1.1.1.2'!Y21/Deflactores!$B21*100 -> 1.0030855 | Z21: =SUM(B21:Y21) -> 24736.476
... A48: 2030 | B48: =+'[1]1.1.1.1.2'!B48/Deflactores!$B48*100 -> #N/A | C48: =+'[1]1.1.1.1.2'!C48/Deflactores!$B48*100 -> #N/A | D48: =+'[1]1.1.1.1.2'!D48/Deflactores!$B48*100 -> #N/A | E48: =+'[1]1.1.1.1.2'!E48/Deflactores!$B48*100 -> #N/A | F48: =+'[1]1.1.1.1.2'!F48/Deflactores!$B48*100 -> #N/A | G48: =+'[1]1.1.1.1.2'!G48/Deflactores!$B48*100 -> #N/A | H48: =+'[1]1.1.1.1.2'!H48/Deflactores!$B48*100 -> #N/A | I48: =+'[1]1.1.1.1.2'!I48/Deflactores!$B48*100 -> #N/A | ... Y48: =+'[1]1.1.1.1.2'!Y48/Deflactores!$B48*100 -> #N/A | Z48: =SUM(B48:Y48) -> #N/A
