Workbook
Name adfsd: #REF!
Name adsf: #REF!
Name AJESTA: #REF!
Name ALFA: #REF!
Name CEMENTO: #REF!
Name CICESP: #REF!
Name CO: #REF!
Name COMB: #REF!
Name CONSTRUC: #REF!
Name DIFTA: #REF!
Name EEI: #REF!
Name EMPLEO: #REF!
Name EPH: #REF!
Name EPH_POB: #REF!
Name FAE_BOVINOS: #REF!
Name GAS: #REF!
Name ICC_FM: #REF!
Name IDL_UTDT: #REF!
Name IND_ACEITERA: #REF!
Name IPC_GBA: #REF!
Name IPC_NAC: #REF!
Name IPC_SFE: #REF!
Name IPM: #REF!
Name IPMPE: #REF!
Name IRR: #REF!
Name LACTEA: #REF!
Name MAQ_AGR: #REF!
Name NA: #REF!
Name OLE_LINK1: '1.2'!#REF!
Name OLE_LINK1: '1.3'!#REF!
Name OLE_LINK1: '1.4'!#REF!
Name OLE_LINK1: '1.5'!#REF!
Name OLE_LINK1: '1.6'!#REF!
Name OLE_LINK1: '1.7'!#REF!
Name OLE_LINK1: '1.8'!#REF!
Name OLE_LINK1: '1.9'!#REF!
Name OLE_LINK2: '1.2'!#REF!
Name OLE_LINK2: '1.3'!#REF!
Name OLE_LINK2: '1.4'!#REF!
Name OLE_LINK2: '1.5'!#REF!
Name OLE_LINK2: '1.6'!#REF!
Name OLE_LINK2: '1.7'!#REF!
Name OLE_LINK2: '1.8'!#REF!
Name OLE_LINK2: '1.9'!#REF!
Name PATENTES: #REF!
Name PBG: #REF!
Name PGCLAS: #REF!
Name PGCREC: #REF!
Name REC: #REF!
Name sct: #REF!
Name T: #REF!
Name Trigo: #REF!
Name VARCRI: #REF!
Name VARTA: #REF!
Name VENTAS: #REF!
Name XCER: #REF!

Sheet INDICE
E2: Centro de Estudios y Servicios - Bolsa de Comercio de Santa Fe -
E3: San Martín 2231 - 3000 - Santa Fe - Argentina
E4: Tel Fax: (0342) 4845800
E5: Email: ces@bcsf.com.ar
E6: Websites: https://bcsf.com.ar/ces/ o bien https://bcsf.com.ar/
C8: BASE DE DATOS DEL ÍNDICE COMPUESTO COINCIDENTE DE LA PROVINCIA DE SANTA FE Y SUS SERIES COMPONENTES
C10: Última actualización: 06/10/2026
C12: ICA-SFE y series componentes | F12: Frecuencia | G12: Nº de series | H12: Fecha de inicio
C13: 1.1. Índice de Actividad Económica de la provincia de Santa Fe (ICA-SFE) | F13: Mensual | G13: =COLUMNS('1.1'!B:O) -> 14 | H13: 1994.01
C14: 1.2. Puestos de trabajo formal en la provincia de Santa Fe | F14: Mensual | G14: =COLUMNS('1.2'!B:C) -> 2 | H14: 1994.01
C15: 1.3. Expectativas empresarias para tomar personal en la provincia de Santa Fe | F15: Mensual | G15: =COLUMNS('1.2'!B:C) -> 2 | H15: 1994.01
C16: 1.4. Remuneración al factor trabajo en la provincia de Santa Fe | F16: Mensual | G16: =COLUMNS('1.2'!B:C) -> 2 | H16: 1994.01 | J16: Remuneración al factor trabajo en la provincia de Santa Fe | K16: Puestos de trabajo formal en la provincia de Santa Fe
C17: 1.5. Índice Compuesto de Evolución Industrial (ICEI) de la provincia de Santa Fe | F17: Mensual | G17: =COLUMNS('1.2'!B:C) -> 2 | H17: 1994.01
C18: 1.6. Ventas en supermercados de gran superficie en la provincia de Santa Fe | F18: Mensual | G18: =COLUMNS('1.2'!B:C) -> 2 | H18: 1994.01
C19: 1.7. Consumo de cemento en la provincia de Santa Fe | F19: Mensual | G19: =COLUMNS('1.2'!B:C) -> 2 | H19: 1994.01
C20: 1.8. Patentamiento de automotores en la provincia de Santa Fe | F20: Mensual | G20: =COLUMNS('1.2'!B:C) -> 2 | H20: 1994.01
C21: 1.9. Recursos tributarios de la provincia de Santa Fe | F21: Mensual | G21: =COLUMNS('1.2'!B:C) -> 2 | H21: 1994.01
E23: Total de series mensuales | G23: =SUM(G13:G21) -> 30

Sheet 1.1
A1: VOLVER AL ÍNDICE
A2: Título | B2: Índice Compuesto Coincidente de Actividad Económica de la provincia de Santa Fe (ICA-SFE) | P2: Índice Compuesto Coincidente de Actividad Económica de Argentina (ICA-ARG)
A3: Fuentes | B3: Centro de Estudios y Servicios (CES) - Bolsa de Comercio de Santa Fe (BCSF) | P3: Centro de Investigación del Ciclo Económico (CICEc)
A4: Info nivel 1
A5: Info nivel 2 | B5: Nivel | C5: Tasa de cambio mensual | D5: Tasa de cambio Interanual | E5: Variaciones Anuales Suavizadas (VAS) de 6 meses | F5: Variaciones Anuales Suavizadas (VAS) de 12 meses | G5: Tasas críticas: límite superior | H5: Tasas críticas: límite inferior | I5: Tasas críticas: promedio anual largo plazo | J5: Tendencia HP del ICA-SFE | K5: Desvíos de la tendencia | L5: ICA-SFE sin tendencia (ICA-SFE_NT) | M5: Índice de difusión de series componentes | N5: Recesión Santa Fe | O5: Desaceleración Santa Fe | P5: Recesión Argentina (ICA-ARG)
A6: Info nivel 3
A7: Unidad de medida | B7: Índice base 2004=100 | C7: % | D7: % | E7: % | F7: % | G7: % | H7: % | I7: % | J7: Números índice: sin base propia | K7: (%) | L7: Índice Base 2004=100 | M7: (%) | N7: 1 = contracción y 0 = expansión | O7: 1 = desaceleración y 0 = aceleración | P7: 1 = contracción y 0 = expansión
A8: Tipo numérico | B8: float | C8: float | D8: float | E8: float | F8: float | G8: float | H8: float | I8: float | J8: float | K8: float | L8: float | M8: float | N8: integrer | O8: integrer | P8: integrer
A9: CODIGO | B9: 1.1.1 | C9: 1.1.2 | D9: 1.1.3 | E9: 1.1.4 | F9: 1.1.5 | G9: 1.1.6 | H9: 1.1.7 | I9: 1.1.8 | J9: 1.1.9 | K9: 1.1.10 | L9: 1.1.11 | M9: 1.1.12 | N9: 1.1.13 | O9: 1.1.14 | P9: 1.1.15
A10: 1994.01 | B10: 80.525888 | J10: 77.181759 | K10: 0.04118818 | L10: 98.281557 | N10: 0 | O10: 0 | P10: 0
A11: 1994.02 | B11: 80.22119 | C11: -0.0037910314 | J11: 77.314355 | K11: 0.035614991 | L11: 97.754412 | N11: 0 | O11: 0 | P11: 0
A12: 1994.03 | B12: 80.425226 | C12: 0.0025401924 | J12: 77.446978 | K12: 0.03661361 | L12: 97.847633 | N12: 0 | O12: 0 | P12: 0
A13: 1994.04 | B13: 80.565386 | C13: 0.0017412183 | J13: 77.579673 | K13: 0.036783561 | L13: 97.862722 | N13: 0 | O13: 0 | P13: 0
A14: 1994.05 | B14: 80.937666 | C14: 0.0046101958 | J14: 77.712513 | K14: 0.03993096 | L14: 98.159026 | N14: 0 | O14: 0 | P14: 0
A15: 1994.06 | B15: 80.959637 | C15: 0.00027142181 | J15: 77.845593 | K15: 0.038568944 | L15: 98.029972 | N15: 0 | O15: 0 | P15: 0
A16: 1994.07 | B16: 81.223823 | C16: 0.0032578619 | J16: 77.97903 | K16: 0.040306319 | L16: 98.193902 | M16: 54.608692 | N16: 0 | O16: 0 | P16: 0
A17: 1994.08 | B17: 80.785078 | C17: -0.0054163136 | J17: 78.112969 | K17: 0.033040412 | L17: 97.508619 | M17: 51.245592 | N17: 0 | O17: 0 | P17: 0
A18: 1994.09 | B18: 81.605105 | C18: 0.010099552 | J18: 78.247579 | K18: 0.041857335 | L18: 98.342207 | M18: 51.245592 | N18: 0 | O18: 0 | P18: 0
A19: 1994.1 | B19: 81.930054 | C19: 0.0039740559 | J19: 78.38305 | K19: 0.044321751 | L19: 98.577234 | M19: 54.608692 | N19: 0 | O19: 0 | P19: 0
A20: 1994.11 | B20: 81.984111 | C20: 0.0006595759 | J20: 78.519596 | K20: 0.043314328 | L20: 98.485851 | M20: 52.927142 | N20: 0 | O20: 1 | P20: 1
A21: 1994.12 | B21: 81.674075 | C21: -0.0037888244 | J21: 78.657461 | K21: 0.037664686 | L21: 97.957826 | M21: 47.882493 | N21: 1 | O21: 1 | P21: 1
A22: 1995.01 | B22: 81.012492 | C22: -0.0081332669 | D22: 0.0060246375 | E22: 0.0060246375 | G22: -0.012387319 | H22: 0.050154156 | I22: 0.018883419 | J22: 78.796916 | K22: 0.027551544 | L22: 97.010261 | M22: 41.156294 | N22: 1 | O22: 1 | P22: 1
A23: 1995.02 | B23: 80.175846 | C23: -0.010381063 | D23: -0.0005653945 | E23: -0.0005653945 | G23: -0.012387319 | H23: 0.050154156 | I23: 0.018883419 | J23: 78.938253 | K23: 0.015228717 | L23: 95.856154 | M23: 41.156294 | N23: 1 | O23: 1 | P23: 1
A24: 1995.03 | B24: 79.128296 | C24: -0.013151761 | D24: -0.016257348 | E24: -0.016257348 | G24: -0.012387319 | H24: 0.050154156 | I24: 0.018883419 | J24: 79.081783 | K24: 0.00025126235 | L24: 94.453711 | M24: 36.111644 | N24: 1 | O24: 1 | P24: 1
A25: 1995.04 | B25: 77.128241 | C25: -0.025601038 | D25: -0.043599603 | E25: -0.043599603 | G25: -0.012387319 | H25: 0.050154156 | I25: 0.018883419 | J25: 79.227827 | K25: -0.026728097 | L25: 91.920293 | M25: 27.703896 | N25: 1 | O25: 1 | P25: 1
A26: 1995.05 | B26: 76.394685 | C26: -0.0095563754 | D26: -0.057766175 | E26: -0.057766175 | G26: -0.012387319 | H26: 0.050154156 | I26: 0.018883419 | J26: 79.376705 | K26: -0.037696268 | L26: 90.901675 | M26: 24.340796 | N26: 1 | O26: 1 | P26: 1
A27: 1995.06 | B27: 76.208264 | C27: -0.002443216 | D27: -0.060480812 | E27: -0.060480812 | G27: -0.012387319 | H27: 0.050154156 | I27: 0.018883419 | J27: 79.528722 | K27: -0.041785958 | L27: 90.536057 | M27: 29.385445 | N27: 1 | O27: 1 | P27: 1
A28: 1995.07 | B28: 75.452774 | C28: -0.0099629609 | D28: -0.073701635 | E28: -0.073701635 | F28: -0.1011091 | G28: -0.012387319 | H28: 0.050154156 | I28: 0.018883419 | J28: 79.68416 | K28: -0.053046221 | L28: 89.496382 | M28: 27.703896 | N28: 1 | O28: 1 | P28: 1
A29: 1995.08 | B29: 74.952203 | C29: -0.0066563381 | D29: -0.07494166 | E29: -0.07494166 | F29: -0.10214064 | G29: -0.012387319 | H29: 0.050154156 | I29: 0.018883419 | J29: 79.843275 | K29: -0.061117166 | L29: 88.761664 | M29: 24.340796 | N29: 1 | O29: 1 | P29: 1
A30: 1995.09 | B30: 74.501408 | C30: -0.0060325923 | D30: -0.091073804 | E30: -0.091073804 | F30: -0.10196879 | G30: -0.012387319 | H30: 0.050154156 | I30: 0.018883419 | J30: 80.006291 | K30: -0.068583235 | L30: 88.087904 | M30: 20.977697 | N30: 1 | O30: 1 | P30: 1
A31: 1995.1 | B31: 74.268966 | C31: -0.0031248342 | D31: -0.098172694 | E31: -0.098172694 | F31: -0.094645055 | G31: -0.012387319 | H31: 0.050154156 | I31: 0.018883419 | J31: 80.173394 | K31: -0.073345783 | L31: 87.673823 | M31: 24.340796 | N31: 1 | O31: 1 | P31: 1
A32: 1995.11 | B32: 73.952506 | C32: -0.0042701046 | D32: -0.10310237 | E32: -0.10310237 | F32: -0.088088427 | G32: -0.012387319 | H32: 0.050154156 | I32: 0.018883419 | J32: 80.344728 | K32: -0.079187032 | L32: 87.161807 | M32: 24.340796 | N32: 1 | O32: 1 | P32: 1
A33: 1995.12 | B33: 73.881945 | C33: -0.00095460312 | D33: -0.10026815 | E33: -0.10026815 | F33: -0.075046112 | G33: -0.012387319 | H33: 0.050154156 | I33: 0.018883419 | J33: 80.520392 | K33: -0.082001399 | L33: 86.940556 | M33: 24.340796 | N33: 1 | O33: 1 | P33: 0
A34: 1996.01 | B34: 74.523565 | C34: 0.0086469095 | D34: -0.083487977 | E34: -0.083487977 | F34: -0.045366313 | G34: -0.012387319 | H34: 0.050154156 | I34: 0.018883419 | J34: 80.700434 | K34: -0.076027062 | L34: 87.556518 | M34: 31.066995 | N34: 0 | O34: 0 | P34: 0
A35: 1996.02 | B35: 75.555337 | C35: 0.013749944 | D35: -0.059356969 | E35: -0.059356969 | F35: -0.0079022145 | G35: -0.012387319 | H35: 0.050154156 | I35: 0.018883419 | J35: 80.884852 | K35: -0.06530585 | L35: 88.627964 | M35: 42.837844 | N35: 0 | O35: 0 | P35: 0
A36: 1996.03 | B36: 75.65191 | C36: 0.0012773526 | D36: -0.044927856 | E36: -0.044927856 | F36: 0.0038236866 | G36: -0.012387319 | H36: 0.050154156 | I36: 0.018883419 | J36: 81.073598 | K36: -0.066229467 | L36: 88.600522 | M36: 51.245592 | N36: 0 | O36: 0 | P36: 0
A37: 1996.04 | B37: 77.000721 | C37: 0.0176721 | D37: -0.0016547181 | E37: -0.0016547181 | F37: 0.044501426 | G37: -0.012387319 | H37: 0.050154156 | I37: 0.018883419 | J37: 81.266581 | K37: -0.051781025 | L37: 90.037192 | M37: 57.971792 | N37: 0 | O37: 0 | P37: 0
A38: 1996.05 | B38: 77.53963 | C38: 0.0069743779 | D38: 0.014876035 | E38: 0.014876035 | F38: 0.058313203 | G38: -0.012387319 | H38: 0.050154156 | I38: 0.018883419 | J38: 81.463668 | K38: -0.047402116 | L38: 90.523563 | M38: 64.697991 | N38: 0 | O38: 0 | P38: 0
A39: 1996.06 | B39: 78.053646 | C39: 0.0066071964 | D39: 0.023926448 | E39: 0.023926448 | F39: 0.068796454 | G39: -0.012387319 | H39: 0.050154156 | I39: 0.018883419 | J39: 81.664695 | K39: -0.043399695 | L39: 90.97915 | M39: 66.37954 | N39: 0 | O39: 0 | P39: 0
... A177: 2007.12 | B177: 130.50009 | C177: 0.0083023197 | D177: 0.079653356 | E177: 0.079653356 | F177: 0.091785586 | G177: -0.012387319 | H177: 0.050154156 | I177: 0.018883419 | J177: 124.15315 | K177: 0.051955015 | L177: 122.19263 | M177: 74.787289 | N177: 0 | O177: 0 | P177: 0
...

Sheet 1.2
A1: VOLVER AL ÍNDICE
A2: Título | B2: Puestos de trabajo formal en la provincia de Santa Fe: privados, públicos nacionales y públicos provinciales
A3: Fuentes | B3: Agencia de Recaudación y Control Aduanero (ARCA) y Ministerio de Economía de la provincia de Santa Fe
A4: Info nivel 1
A5: Info nivel 2 | B5: Serie original | C5: Serie filtrada
A6: Info nivel 3
A7: Unidad de medida | B7: Miles de asalariados | C7: Miles de asalariados
A8: Tipo numérico | B8: float | C8: float
A9: CODIGO | B9: 1.2.1 | C9: 1.2.2
A10: 1994.01 | B10: 369.20799 | C10: 375.2179
A11: 1994.02 | B11: 371.52175 | C11: 368.98755
A12: 1994.03 | B12: 369.40174 | C12: 371.87608
A13: 1994.04 | B13: 373.79485 | C13: 371.98332
A14: 1994.05 | B14: 374.9627 | C14: 372.79662
A15: 1994.06 | B15: 377.22082 | C15: 372.81333
A16: 1994.07 | B16: 373.60547 | C16: 377.74791
A17: 1994.08 | B17: 373.85471 | C17: 375.38059
A18: 1994.09 | B18: 380.66983 | C18: 381.78905
A19: 1994.1 | B19: 384.23495 | C19: 383.64305
A20: 1994.11 | B20: 381.2506 | C20: 383.81992
A21: 1994.12 | B21: 380.3614 | C21: 383.13026
... A177: 2007.12 | B177: 605.60916 | C177: 601.09168
A178: =A166+1 -> 2008.01 | B178: 613.79191 | C178: 604.62339
A179: =A167+1 -> 2008.02 | B179: 602.86289 | C179: 605.83469
A180: =A168+1 -> 2008.03 | B180: 603.15157 | C180: 609.68169
A181: =A169+1 -> 2008.04 | B181: 610.7752 | C181: 609.00502
A182: =A170+1 -> 2008.05 | B182: 613.08993 | C182: 612.41366
A183: =A171+1 -> 2008.06 | B183: 609.35457 | C183: 616.30879
A184: =A172+1 -> 2008.07 | B184: 618.578 | C184: 619.55312
A185: =A173+1 -> 2008.08 | B185: 619.374 | C185: 622.01672
A186: =A174+1 -> 2008.09 | B186: 621.653 | C186: 623.7899
A187: =A175+1 -> 2008.1 | B187: 623.934 | C187: 623.62686
A188: =A176+1 -> 2008.11 | B188: 627.839 | C188: 622.72699
A189: =A177+1 -> 2008.12 | B189: 625.609 | C189: 621.19208
... A401: =A389+1 -> 2026.08 | B401: 730.05862 | C401: 732.22448
A402: =A390+1 -> 2026.09 | B402: #N/A | C402: #N/A
A403: =A391+1 -> 2026.1 | B403: #N/A | C403: #N/A
A404: =A392+1 -> 2026.11 | B404: #N/A | C404: #N/A
A405: =A393+1 -> 2026.12 | B405: #N/A | C405: #N/A
A406: =A394+1 -> 2027.01 | B406: #N/A | C406: #N/A
...

Sheet 1.3
A1: VOLVER AL ÍNDICE
A2: Título | B2: Expectativas empresarias para tomar personal en la provincia de Santa Fe
A3: Fuentes | B3: Centro de Investigación en Finanzas de UTDT y Encuesta de Indicadores Laborales (EIL) del Ministerio de Capital Humano de la Nación
A4: Info nivel 1
A5: Info nivel 2 | B5: Serie original | C5: Serie filtrada
A6: Info nivel 3
A7: Unidad de medida | B7: Índice base 2010=100 | C7: Índice base 2010=100
A8: Tipo numérico | B8: float | C8: float
A9: CODIGO | B9: 1.3.1 | C9: 1.3.2
A10: 1994.01 | C10: 190.28833
A11: 1994.02 | C11: 192.40554
A12: 1994.03 | C12: 192.13776
A13: 1994.04 | C13: 186.34679
A14: 1994.05 | C14: 176.04615
A15: 1994.06 | C15: 163.12557
A16: 1994.07 | C16: 149.67459
A17: 1994.08 | C17: 137.73574
A18: 1994.09 | C18: 128.46629
A19: 1994.1 | C19: 121.99863
A20: 1994.11 | C20: 118.04609
A21: 1994.12 | C21: 115.63801
... A81: 1999.12 | C81: 120.8128
A82: 2000.01 | B82: 178.39252 | C82: 121.28563
A83: 2000.02 | B83: 67.738008 | C83: 122.8433
A84: 2000.03 | B84: 107.18616 | C84: 124.42098
A85: 2000.04 | B85: 58.45403 | C85: 126.01892
A86: 2000.05 | B86: 94.048453 | C86: 127.63739
A87: 2000.06 | B87: 122.33831 | C87: 129.27664
A88: 2000.07 | B88: 128.88965 | C88: 130.93694
A89: 2000.08 | B89: 138.17363 | C89: 132.61857
A90: 2000.09 | B90: 162.32949 | C90: 135.30669
A91: 2000.1 | B91: 195.41899 | C91: 136.20589
A92: 2000.11 | B92: 177.93708 | C92: 136.54017
A93: 2000.12 | B93: 152.67765 | C93: 137.79847
... A177: 2007.12 | B177: 68.361733 | C177: 78.408194
A178: =A166+1 -> 2008.01 | B178: 97.762691 | C178: 83.539268
A179: =A167+1 -> 2008.02 | B179: 72.446971 | C179: 87.904934
A180: =A168+1 -> 2008.03 | B180: 113.35184 | C180: 89.888107
A181: =A169+1 -> 2008.04 | B181: 120.72727 | C181: 90.305889
A182: =A170+1 -> 2008.05 | B182: 86.470707 | C182: 88.396343
...

Sheet 1.4
A1: VOLVER AL ÍNDICE
A2: Título | B2: Remuneración al factor trabajo en la provincia de Santa Fe | Salario medio real por cantidad de trabajadores formales
A3: Fuente | B3: Agencia de Recaudación y Control Aduanero (ARCA) en base al Sistema Integrado Previsional Argentino (SIPA)
A4: Info nivel 1
A5: Info nivel 2 | B5: Serie original | C5: Serie filtrada
A6: Info nivel 3
A7: Unidad de medida | B7: Millones de pesos de 1993 | C7: Millones de pesos de 1993
A8: Tipo numérico | B8: float | C8: float
A9: CODIGO | B9: 1.4.1 | C9: 1.4.2
A10: 1994.01 | B10: 199.96138 | C10: 199.96138
A11: 1994.02 | B11: 198.78854 | C11: 198.78854
A12: 1994.03 | B12: 197.11001 | C12: 197.11001
A13: 1994.04 | B13: 197.99294 | C13: 197.99294
A14: 1994.05 | B14: 197.91803 | C14: 197.91803
A15: 1994.06 | B15: 197.12373 | C15: 197.12373
A16: 1994.07 | B16: 201.03488 | C16: 201.03488
A17: 1994.08 | B17: 199.78237 | C17: 199.78237
A18: 1994.09 | B18: 205.91387 | C18: 205.91387
A19: 1994.1 | B19: 207.74151 | C19: 207.74151
A20: 1994.11 | B20: 210.17502 | C20: 210.17502
A21: 1994.12 | B21: 207.01461 | C21: 207.01461
... A177: 2007.12 | B177: 432.65867 | C177: 432.65867
A178: =A166+1 -> 2008.01 | B178: 438.04122 | C178: 438.04122
A179: =A167+1 -> 2008.02 | B179: 434.29987 | C179: 434.29987
A180: =A168+1 -> 2008.03 | B180: 442.2903 | C180: 442.2903
A181: =A169+1 -> 2008.04 | B181: 440.57147 | C181: 440.57147
A182: =A170+1 -> 2008.05 | B182: 449.02235 | C182: 449.02235
A183: =A171+1 -> 2008.06 | B183: 452.96214 | C183: 452.96214
A184: =A172+1 -> 2008.07 | B184: 458.80544 | C184: 458.80544
A185: =A173+1 -> 2008.08 | B185: 462.9149 | C185: 462.9149
A186: =A174+1 -> 2008.09 | B186: 468.97037 | C186: 468.97037
A187: =A175+1 -> 2008.1 | B187: 474.58308 | C187: 474.58308
A188: =A176+1 -> 2008.11 | B188: 475.30689 | C188: 475.30689
A189: =A177+1 -> 2008.12 | B189: 476.43165 | C189: 476.43165
... A401: =A389+1 -> 2026.08 | B401: 533.69091 | C401: 533.69091
A402: =A390+1 -> 2026.09 | B402: #N/A | C402: #N/A
A403: =A391+1 -> 2026.1 | B403: #N/A | C403: #N/A
A404: =A392+1 -> 2026.11 | B404: #N/A | C404: #N/A
A405: =A393+1 -> 2026.12 | B405: #N/A | C405: #N/A
A406: =A394+1 -> 2027.01 | B406: #N/A | C406: #N/A
...

Sheet 1.5
A1: VOLVER AL ÍNDICE
A2: Título | B2: Índice Compuesto de Evolución Industrial (ICEI) de la provincia de Santa Fe
A3: Fuente | B3: CES-BCSF
A4: Info nivel 1
A5: Info nivel 2 | B5: Serie original | C5: Serie filtrada
A6: Info nivel 3
A7: Unidad de medida | B7: Índice base 2004=100 | C7: Índice base 2004=100
A8: Tipo numérico | B8: float | C8: float
A9: CODIGO | B9: 1.5.1 | C9: 1.5.2
A10: 1994.01 | B10: 71.919499 | C10: 71.394676
A11: 1994.02 | B11: 71.802791 | C11: 71.583295
A12: 1994.03 | B12: 71.843703 | C12: 71.857793
A13: 1994.04 | B13: 72.564744 | C13: 72.711077
A14: 1994.05 | B14: 73.531926 | C14: 73.592431
A15: 1994.06 | B15: 74.345423 | C15: 74.262783
A16: 1994.07 | B16: 74.557445 | C16: 74.585207
A17: 1994.08 | B17: 74.40516 | C17: 75.049338
A18: 1994.09 | B18: 74.698568 | C18: 75.77222
A19: 1994.1 | B19: 75.614215 | C19: 76.418131
A20: 1994.11 | B20: 76.75629 | C20: 77.345078
A21: 1994.12 | B21: 77.679074 | C21: 77.869507
... A177: 2007.12 | B177: 116.20374 | C177: 115.49239
A178: =A166+1 -> 2008.01 | B178: 115.94714 | C178: 115.30418
A179: =A167+1 -> 2008.02 | B179: 115.0425 | C179: 114.70264
A180: =A168+1 -> 2008.03 | B180: 113.78268 | C180: 113.79893
A181: =A169+1 -> 2008.04 | B181: 112.94729 | C181: 113.01103
A182: =A170+1 -> 2008.05 | B182: 112.28513 | C182: 112.51895
A183: =A171+1 -> 2008.06 | B183: 112.25154 | C183: 112.57439
A184: =A172+1 -> 2008.07 | B184: 112.85956 | C184: 112.94305
A185: =A173+1 -> 2008.08 | B185: 113.05858 | C185: 112.82475
A186: =A174+1 -> 2008.09 | B186: 111.96461 | C186: 111.86802
A187: =A175+1 -> 2008.1 | B187: 110.42102 | C187: 110.68122
A188: =A176+1 -> 2008.11 | B188: 109.60163 | C188: 109.82287
A189: =A177+1 -> 2008.12 | B189: 109.08813 | C189: 109.29988
... A400: =A388+1 -> 2026.07 | B400: 116.30308 | C400: 116.00932
A401: =A389+1 -> 2026.08 | B401: #N/A | C401: #N/A
A402: =A390+1 -> 2026.09 | B402: #N/A | C402: #N/A
A403: =A391+1 -> 2026.1 | B403: #N/A | C403: #N/A
A404: =A392+1 -> 2026.11 | B404: #N/A | C404: #N/A
A405: =A393+1 -> 2026.12 | B405: #N/A | C405: #N/A
...

Sheet 1.6
A1: VOLVER AL ÍNDICE
A2: Título | B2: Ventas en supermercados de gran superficie en la provincia de Santa Fe
A3: Fuente | B3: Instituto Nacional de Estadísticas y Censos (INDEC)
A4: Info nivel 1
A5: Info nivel 2 | B5: Serie original | C5: Serie filtrada
A6: Info nivel 3
A7: Unidad de medida | B7: Millones de pesos de 1993 | C7: Millones de pesos de 1993
A8: Tipo numérico | B8: float | C8: float
A9: CODIGO | B9: 1.6.1 | C9: 1.6.2
A10: 1994.01 | C10: 33.89645
A11: 1994.02 | C11: 34.038207
A12: 1994.03 | C12: 34.123272
A13: 1994.04 | C13: 33.328627
A14: 1994.05 | C14: 33.288651
A15: 1994.06 | C15: 33.361712
A16: 1994.07 | C16: 33.646952
A17: 1994.08 | C17: 33.755351
A18: 1994.09 | C18: 33.765364
A19: 1994.1 | C19: 33.645943
A20: 1994.11 | C20: 33.697871
A21: 1994.12 | C21: 33.48372
... A45: 1996.12 | C45: 34.776852
A46: 1997.01 | B46: 33.479706 | C46: 36.78488
A47: 1997.02 | B47: 33.306008 | C47: 36.454986
A48: 1997.03 | B48: 37.969299 | C48: 36.366331
A49: 1997.04 | B49: 35.713542 | C49: 37.055981
A50: 1997.05 | B50: 37.59809 | C50: 37.878598
A51: 1997.06 | B51: 36.943931 | C51: 38.020891
A52: 1997.07 | B52: 37.669391 | C52: 37.913092
A53: 1997.08 | B53: 38.978862 | C53: 38.133797
A54: 1997.09 | B54: 34.313226 | C54: 38.70609
A55: 1997.1 | B55: 37.914622 | C55: 39.786059
A56: 1997.11 | B56: 40.687751 | C56: 41.043704
A57: 1997.12 | B57: 53.093408 | C57: 41.69652
... A177: 2007.12 | B177: 78.838801 | C177: 62.139985
A178: =A166+1 -> 2008.01 | B178: 59.872279 | C178: 63.156618
A179: =A167+1 -> 2008.02 | B179: 59.22592 | C179: 63.667495
A180: =A168+1 -> 2008.03 | B180: 66.154138 | C180: 63.493059
A181: =A169+1 -> 2008.04 | B181: 59.323419 | C181: 63.361505
A182: =A170+1 -> 2008.05 | B182: 61.653383 | C182: 63.042462
...

Sheet 1.7
A1: VOLVER AL ÍNDICE
A2: Título | B2: Consumo de cemento en la provincia Santa Fe
A3: Fuente | B3: Asociación de Fabricantes de Cemento Pórtland (AFCP)
A4: Info nivel 1
A5: Info nivel 2 | B5: Serie original | C5: Serie filtrada
A6: Info nivel 3
A7: Unidad de medida | B7: Miles de toneladas | C7: Miles de toneladas
A8: Tipo numérico | B8: float | C8: float
A9: CODIGO | B9: 1.7.1 | C9: 1.7.2
A10: 1994.01 | C10: 35.88957
A11: 1994.02 | C11: 37.319697
A12: 1994.03 | C12: 36.976779
A13: 1994.04 | C13: 37.880883
A14: 1994.05 | C14: 38.975589
A15: 1994.06 | C15: 39.531145
A16: 1994.07 | C16: 40.401014
A17: 1994.08 | C17: 39.825332
A18: 1994.09 | C18: 39.506528
A19: 1994.1 | C19: 40.456296
A20: 1994.11 | C20: 41.35225
A21: 1994.12 | C21: 40.482123
... A81: 1999.12 | C81: 41.420114
A82: 2000.01 | B82: 40.585 | C82: 40.838143
A83: 2000.02 | B83: 34.964 | C83: 39.000186
A84: 2000.03 | B84: 43.151 | C84: 38.723769
A85: 2000.04 | B85: 34.179 | C85: 37.746015
A86: 2000.05 | B86: 31.178 | C86: 34.510284
A87: 2000.06 | B87: 32.952 | C87: 33.093271
A88: 2000.07 | B88: 34.814 | C88: 34.406017
A89: 2000.08 | B89: 41.098 | C89: 35.973665
A90: 2000.09 | B90: 44.592 | C90: 35.171204
A91: 2000.1 | B91: 32.797 | C91: 33.429329
A92: 2000.11 | B92: 35.82 | C92: 34.42226
A93: 2000.12 | B93: 33.641 | C93: 36.917703
... A177: 2007.12 | B177: 83.3767 | C177: 90.605506
A178: =A166+1 -> 2008.01 | B178: 84.05841 | C178: 85.976223
A179: =A167+1 -> 2008.02 | B179: 77.3513 | C179: 83.026449
A180: =A168+1 -> 2008.03 | B180: 73.80793 | C180: 84.43306
A181: =A169+1 -> 2008.04 | B181: 86.68636 | C181: 87.274804
A182: =A170+1 -> 2008.05 | B182: 85.1493 | C182: 86.661472
...

Sheet 1.8
A1: VOLVER AL ÍNDICE
A2: Título | B2: Patentamientos de automotores en la provincia de Santa Fe
A3: Fuente | B3: Dirección Nacional de Registro de la Propiedad Automotor de Argentina (DNRPA)
A4: Info nivel 1
A5: Info nivel 2 | B5: Serie original | C5: Serie filtrada
A6: Info nivel 3
A7: Unidad de medida | B7: Miles de vehículos | C7: Miles de vehículos
A8: Tipo numérico | B8: float | C8: float
A9: CODIGO | B9: 1.8.1 | C9: 1.8.2
A10: 1994.01 | B10: 6.2062289 | C10: 3.2189796
A11: 1994.02 | B11: 3.0353094 | C11: 3.1461635
A12: 1994.03 | B12: 3.0034704 | C12: 3.1334257
A13: 1994.04 | B13: 3.3419063 | C13: 3.2887411
A14: 1994.05 | B14: 3.3666699 | C14: 3.4127806
A15: 1994.06 | B15: 3.1614858 | C15: 3.5204666
A16: 1994.07 | B16: 3.8713755 | C16: 3.5589895
A17: 1994.08 | B17: 3.4079425 | C17: 3.4383875
A18: 1994.09 | B18: 3.722794 | C18: 3.4899815
A19: 1994.1 | B19: 3.5211475 | C19: 3.518306
A20: 1994.11 | B20: 2.1638666 | C20: 3.2662338
A21: 1994.12 | B21: 1.2028032 | C21: 3.1670021
... A177: 2007.12 | B177: 1.986 | C177: 4.7732317
A178: =A166+1 -> 2008.01 | B178: 8.184 | C178: 4.7017679
A179: =A167+1 -> 2008.02 | B179: 4.381 | C179: 4.739633
A180: =A168+1 -> 2008.03 | B180: 4.184 | C180: 4.8517433
A181: =A169+1 -> 2008.04 | B181: 5.226 | C181: 4.986019
A182: =A170+1 -> 2008.05 | B182: 5.227 | C182: 4.9571316
A183: =A171+1 -> 2008.06 | B183: 4.256 | C183: 4.7610992
A184: =A172+1 -> 2008.07 | B184: 5.235 | C184: 4.7301153
A185: =A173+1 -> 2008.08 | B185: 5.022 | C185: 4.7530728
A186: =A174+1 -> 2008.09 | B186: 5.187 | C186: 4.6441066
A187: =A175+1 -> 2008.1 | B187: 4.561 | C187: 4.3819739
A188: =A176+1 -> 2008.11 | B188: 2.787 | C188: 4.0195013
A189: =A177+1 -> 2008.12 | B189: 1.34 | C189: 3.7923334
... A402: =A390+1 -> 2026.09 | B402: 4.725 | C402: 4.2225089
A403: =A391+1 -> 2026.1 | B403: #N/A | C403: #N/A
A404: =A392+1 -> 2026.11 | B404: #N/A | C404: #N/A
A405: =A393+1 -> 2026.12 | B405: #N/A | C405: #N/A
A406: =A394+1 -> 2027.01 | B406: #N/A | C406: #N/A
A407: =A395+1 -> 2027.02 | B407: #N/A | C407: #N/A
...

Sheet 1.9
A1: VOLVER AL ÍNDICE
A2: Título | B2: Recursos tributarios de la provincia de Santa Fe (recaudación de tributos locales y recursos de origen nacional)
A3: Fuentes | B3: Administración Provincial de Impuestos (API) y Ministerio de Economía de la Nación (MECON)
A4: Info nivel 1
A5: Info nivel 2 | B5: Serie original | C5: Serie filtrada
A6: Info nivel 3
A7: Unidad de medida | B7: Millones de pesos de 1993 | C7: Millones de pesos de 1993
A8: Tipo numérico | B8: float | C8: float
A9: CODIGO | B9: 1.9.1 | C9: 1.9.2
A10: 1992.01 | B10: 146.17031 | C10: 151.1519
A11: 1992.02 | B11: 141.06962 | C11: 150.78585
A12: 1992.03 | B12: 137.86284 | C12: 152.43368
A13: 1992.04 | B13: 139.42855 | C13: 155.6958
A14: 1992.05 | B14: 188.66713 | C14: 159.52465
A15: 1992.06 | B15: 199.94797 | C15: 160.43815
A16: 1992.07 | B16: 157.40557 | C16: 159.95259
A17: 1992.08 | B17: 156.74286 | C17: 161.73443
A18: 1992.09 | B18: 161.35963 | C18: 161.48729
A19: 1992.1 | B19: 144.66914 | C19: 156.9026
A20: 1992.11 | B20: 155.79226 | C20: 154.24821
A21: 1992.12 | B21: 162.87107 | C21: 156.65607
... A201: 2007.12 | B201: 295.45491 | C201: 302.24444
A202: =A190+1 -> 2008.01 | B202: 294.15336 | C202: 304.14078
A203: =A191+1 -> 2008.02 | B203: 297.19219 | C203: 300.50017
A204: =A192+1 -> 2008.03 | B204: 236.9883 | C204: 295.92108
A205: =A193+1 -> 2008.04 | B205: 267.13065 | C205: 292.30766
A206: =A194+1 -> 2008.05 | B206: 335.23442 | C206: 288.60466
A207: =A195+1 -> 2008.06 | B207: 333.1361 | C207: 290.12281
A208: =A196+1 -> 2008.07 | B208: 307.02843 | C208: 295.85203
A209: =A197+1 -> 2008.08 | B209: 301.79364 | C209: 296.34963
A210: =A198+1 -> 2008.09 | B210: 285.39593 | C210: 293.91122
A211: =A199+1 -> 2008.1 | B211: 293.00572 | C211: 290.69228
A212: =A200+1 -> 2008.11 | B212: 269.59499 | C212: 284.16611
A213: =A201+1 -> 2008.12 | B213: 279.65517 | C213: 280.05673
... A425: =A413+1 -> 2026.08 | B425: 378.46922 | C425: 375.76181
A426: =A414+1 -> 2026.09 | B426: #N/A | C426: #N/A
A427: =A415+1 -> 2026.1 | B427: #N/A | C427: #N/A
A428: =A416+1 -> 2026.11 | B428: #N/A | C428: #N/A
A429: =A417+1 -> 2026.12 | B429: #N/A | C429: #N/A
A430: =A418+1 -> 2027.01 | B430: #N/A | C430: #N/A
...
